Workbook

Sheet Poetry 
A1: POETRY | C1: Sequence is by frequency of occurrence on all recitation pitches
C2: Total | D2: d | E2: e | F2: f | G2: g | H2: A | I2: B | J2: C | K2: checksum
A3: PSALMS | B3: shalshelet | C3: 29 | D3: 0 | E3: 4 | F3: 1 | G3: 0 | H3: 20 | I3: 0 | J3: 4 | K3: =SUM(D3:J3)=C3 -> TRUE
A4: PSALMS | B4: pazer | C4: 72 | D4: 29 | E4: 23 | F4: 13 | G4: 0 | H4: 0 | I4: 0 | J4: 7 | K4: =SUM(D4:J4)=C4 -> TRUE
A5: PSALMS | B5: revia-mugrash | C5: 138 | D5: 0 | E5: 3 | F5: 47 | G5: 0 | H5: 88 | I5: 0 | J5: 0 | K5: =SUM(D5:J5)=C5 -> TRUE
A6: PSALMS | B6: illuy | C6: 150 | D6: 3 | E6: 72 | F6: 4 | G6: 3 | H6: 4 | I6: 0 | J6: 64 | K6: =SUM(D6:J6)=C6 -> TRUE
A7: PSALMS | B7: zarqa | C7: 158 | D7: 5 | E7: 81 | F7: 17 | G7: 1 | H7: 11 | I7: 0 | J7: 43 | K7: =SUM(D7:J7)=C7 -> TRUE
A8: PSALMS | B8: tsinnor | C8: 219 | D8: 5 | E8: 71 | F8: 49 | G8: 0 | H8: 0 | I8: 59 | J8: 35 | K8: =SUM(D8:J8)=C8 -> TRUE
A9: PSALMS | B9: qadma | C9: 292 | D9: 1 | E9: 84 | F9: 24 | G9: 3 | H9: 10 | I9: 0 | J9: 170 | K9: =SUM(D9:J9)=C9 -> TRUE
A10: PSALMS | B10: ole | C10: 342 | D10: 150 | E10: 102 | F10: 73 | G10: 0 | H10: 0 | I10: 1 | J10: 16 | K10: =SUM(D10:J10)=C10 -> TRUE
A11: PSALMS | B11: geresh | C11: 1523 | D11: 0 | E11: 63 | F11: 497 | G11: 1 | H11: 961 | I11: 0 | J11: 1 | K11: =SUM(D11:J11)=C11 -> TRUE
A12: PSALMS | B12: revia | C12: 2207 | D12: 5 | E12: 358 | F12: 732 | G12: 14 | H12: 916 | I12: 0 | J12: 182 | K12: =SUM(D12:J12)=C12 -> TRUE
A13: PROVERBS | B13: shalshelet | C13: 4 | D13: 0 | E13: 0 | F13: 0 | G13: 0 | H13: 2 | I13: 0 | J13: 2 | K13: =SUM(D13:J13)=C13 -> TRUE
A14: PROVERBS | B14: pazer | C14: 11 | D14: 5 | E14: 6 | F14: 0 | G14: 0 | H14: 0 | I14: 0 | J14: 0 | K14: =SUM(D14:J14)=C14 -> TRUE
... A32: JOB | B32: revia | C32: 726 | D32: 1 | E32: 82 | F32: 218 | G32: 2 | H32: 389 | I32: 0 | J32: 34 | K32: =SUM(D32:J32)=C32 -> TRUE
D33: =SUM(D3:D32) -> 223

Sheet Poetry-by-chapter
D1: Sequence is by frequency of occurrence on all recitation pitches
D2: Total | E2: d | F2: e | G2: f | H2: g | I2: A | J2: B | K2: C | L2: checksum
A3: PSALMS | B3: 1 | C3: geresh | D3: 3 | E3: 0 | F3: 0 | G3: 2 | H3: 0 | I3: 1 | J3: 0 | K3: 0 | L3: =SUM(E3:K3)=D3 -> TRUE
A4: PSALMS | B4: 1 | C4: illuy | D4: 1 | E4: 0 | F4: 0 | G4: 0 | H4: 0 | I4: 0 | J4: 0 | K4: 1 | L4: =SUM(E4:K4)=D4 -> TRUE
A5: PSALMS | B5: 1 | C5: ole | D5: 3 | E5: 1 | F5: 1 | G5: 1 | H5: 0 | I5: 0 | J5: 0 | K5: 0 | L5: =SUM(E5:K5)=D5 -> TRUE
A6: PSALMS | B6: 1 | C6: qadma | D6: 1 | E6: 0 | F6: 0 | G6: 0 | H6: 0 | I6: 0 | J6: 0 | K6: 1 | L6: =SUM(E6:K6)=D6 -> TRUE
A7: PSALMS | B7: 1 | C7: revia | D7: 8 | E7: 0 | F7: 2 | G7: 4 | H7: 0 | I7: 1 | J7: 0 | K7: 1 | L7: =SUM(E7:K7)=D7 -> TRUE
A8: PSALMS | B8: 1 | C8: tsinnor | D8: 2 | E8: 0 | F8: 1 | G8: 1 | H8: 0 | I8: 0 | J8: 0 | K8: 0 | L8: =SUM(E8:K8)=D8 -> TRUE
A9: PSALMS | B9: 2 | C9: geresh | D9: 9 | E9: 0 | F9: 0 | G9: 0 | H9: 0 | I9: 9 | J9: 0 | K9: 0 | L9: =SUM(E9:K9)=D9 -> TRUE
A10: PSALMS | B10: 2 | C10: illuy | D10: 1 | E10: 0 | F10: 0 | G10: 0 | H10: 0 | I10: 0 | J10: 0 | K10: 1 | L10: =SUM(E10:K10)=D10 -> TRUE
A11: PSALMS | B11: 2 | C11: ole | D11: 1 | E11: 0 | F11: 1 | G11: 0 | H11: 0 | I11: 0 | J11: 0 | K11: 0 | L11: =SUM(E11:K11)=D11 -> TRUE
A12: PSALMS | B12: 2 | C12: pazer | D12: 1 | E12: 0 | F12: 1 | G12: 0 | H12: 0 | I12: 0 | J12: 0 | K12: 0 | L12: =SUM(E12:K12)=D12 -> TRUE
A13: PSALMS | B13: 2 | C13: qadma | D13: 1 | E13: 0 | F13: 0 | G13: 1 | H13: 0 | I13: 0 | J13: 0 | K13: 0 | L13: =SUM(E13:K13)=D13 -> TRUE
A14: PSALMS | B14: 2 | C14: revia | D14: 13 | E14: 0 | F14: 2 | G14: 1 | H14: 0 | I14: 8 | J14: 0 | K14: 2 | L14: =SUM(E14:K14)=D14 -> TRUE
... A1324: JOB | B1324: 42 | C1324: revia | D1324: 4 | E1324: 0 | F1324: 0 | G1324: 2 | H1324: 0 | I1324: 2 | J1324: 0 | K1324: 0 | L1324: =SUM(E1324:K1324)=D1324 -> TRUE

Sheet Prose
A1: PROSE | B1: ornaments on | D1: Sequence is by frequency of occurrence on recitation pitches beginning with d | W1: Paste raw data here | Y1: Total | Z1: c | AA1: d | AB1: e | AC1: f | AD1: g | AE1: A | AF1: B | AG1: C
B2: 1 syllable | C2: Total | D2: c | E2: d | F2: e | G2: f | H2: g | I2: A | J2: B | K2: C | V2: checksum | W2: GENESIS | X2: z-gadol pashta | Y2: 1 | Z2: 0 | AA2: 0 | AB2: 0 | AC2: 0 | AD2: 0 | AE2: 0 | AF2: 1 | AG2: 0 | AH2: 1
A3: GENESIS | B3: =X2 -> z-gadol pashta | C3: =SUM(D3:K3) -> 1 | D3: =Z2 -> 0 | E3: =AA2 -> 0 | F3: =AB2 -> 0 | G3: =AC2 -> 0 | H3: =AD2 -> 0 | I3: =AE2 -> 0 | J3: =AF2 -> 1 | K3: =AG2 -> 0 | L3: =SUM(D3:K3)=Y2 -> TRUE | W3: GENESIS | X3: pashta pashta | Y3: 1 | Z3: 0 | AA3: 0 | AB3: 1 | AC3: 0 | AD3: 0 | AE3: 0 | AF3: 0 | AG3: 0 | AH3: 1
A4: GENESIS | B4: =X3 -> pashta pashta | C4: =SUM(D4:K4) -> 1 | D4: =Z3 -> 0 | E4: =AA3 -> 0 | F4: =AB3 -> 1 | G4: =AC3 -> 0 | H4: =AD3 -> 0 | I4: =AE3 -> 0 | J4: =AF3 -> 0 | K4: =AG3 -> 0 | L4: =SUM(D4:K4)=Y3 -> TRUE | W4: GENESIS | X4: shalshelet | Y4: 3 | Z4: 0 | AA4: 0 | AB4: 3 | AC4: 0 | AD4: 0 | AE4: 0 | AF4: 0 | AG4: 0 | AH4: 1
A5: GENESIS | B5: =X4 -> shalshelet | C5: =SUM(D5:K5) -> 3 | D5: =Z4 -> 0 | E5: =AA4 -> 0 | F5: =AB4 -> 3 | G5: =AC4 -> 0 | H5: =AD4 -> 0 | I5: =AE4 -> 0 | J5: =AF4 -> 0 | K5: =AG4 -> 0 | L5: =SUM(D5:K5)=Y4 -> TRUE | W5: GENESIS | X5: pazer | Y5: 29 | Z5: 0 | AA5: 0 | AB5: 15 | AC5: 0 | AD5: 0 | AE5: 5 | AF5: 9 | AG5: 0 | AH5: 1
A6: GENESIS | B6: =X5 -> pazer | C6: =SUM(D6:K6) -> 29 | D6: =Z5 -> 0 | E6: =AA5 -> 0 | F6: =AB5 -> 15 | G6: =AC5 -> 0 | H6: =AD5 -> 0 | I6: =AE5 -> 5 | J6: =AF5 -> 9 | K6: =AG5 -> 0 | L6: =SUM(D6:K6)=Y5 -> TRUE | W6: GENESIS | X6: telisha-gedola | Y6: 52 | Z6: 0 | AA6: 0 | AB6: 29 | AC6: 0 | AD6: 0 | AE6: 8 | AF6: 15 | AG6: 0 | AH6: 1
A7: GENESIS | B7: =X6 -> telisha-gedola | C7: =SUM(D7:K7) -> 52 | D7: =Z6 -> 0 | E7: =AA6 -> 0 | F7: =AB6 -> 29 | G7: =AC6 -> 0 | H7: =AD6 -> 0 | I7: =AE6 -> 8 | J7: =AF6 -> 15 | K7: =AG6 -> 0 | L7: =SUM(D7:K7)=Y6 -> TRUE | W7: GENESIS | X7: segol | Y7: 72 | Z7: 0 | AA7: 0 | AB7: 11 | AC7: 0 | AD7: 0 | AE7: 0 | AF7: 61 | AG7: 0 | AH7: 1
A8: GENESIS | B8: =X7 -> segol | C8: =SUM(D8:K8) -> 72 | D8: =Z7 -> 0 | E8: =AA7 -> 0 | F8: =AB7 -> 11 | G8: =AC7 -> 0 | H8: =AD7 -> 0 | I8: =AE7 -> 0 | J8: =AF7 -> 61 | K8: =AG7 -> 0 | L8: =SUM(D8:K8)=Y7 -> TRUE | W8: GENESIS | X8: tsinnor | Y8: 73 | Z8: 0 | AA8: 0 | AB8: 19 | AC8: 1 | AD8: 0 | AE8: 0 | AF8: 53 | AG8: 0 | AH8: 1
A9: GENESIS | B9: =X8 -> tsinnor | C9: =SUM(D9:K9) -> 73 | D9: =Z8 -> 0 | E9: =AA8 -> 0 | F9: =AB8 -> 19 | G9: =AC8 -> 1 | H9: =AD8 -> 0 | I9: =AE8 -> 0 | J9: =AF8 -> 53 | K9: =AG8 -> 0 | L9: =SUM(D9:K9)=Y8 -> TRUE | W9: GENESIS | X9: telisha-qetana | Y9: 93 | Z9: 0 | AA9: 0 | AB9: 48 | AC9: 0 | AD9: 0 | AE9: 19 | AF9: 24 | AG9: 2 | AH9: 1
A10: GENESIS | B10: =X9 -> telisha-qetana | C10: =SUM(D10:K10) -> 93 | D10: =Z9 -> 0 | E10: =AA9 -> 0 | F10: =AB9 -> 48 | G10: =AC9 -> 0 | H10: =AD9 -> 0 | I10: =AE9 -> 19 | J10: =AF9 -> 24 | K10: =AG9 -> 2 | L10: =SUM(D10:K10)=Y9 -> TRUE | W10: GENESIS | X10: tarsin | Y10: 113 | Z10: 0 | AA10: 0 | AB10: 66 | AC10: 0 | AD10: 0 | AE10: 29 | AF10: 18 | AG10: 0 | AH10: 1
A11: GENESIS | B11: =X10 -> tarsin | C11: =SUM(D11:K11) -> 113 | D11: =Z10 -> 0 | E11: =AA10 -> 0 | F11: =AB10 -> 66 | G11: =AC10 -> 0 | H11: =AD10 -> 0 | I11: =AE10 -> 29 | J11: =AF10 -> 18 | K11: =AG10 -> 0 | L11: =SUM(D11:K11)=Y10 -> TRUE | W11: GENESIS | X11: zaqef-gadol | Y11: 175 | Z11: 0 | AA11: 0 | AB11: 62 | AC11: 0 | AD11: 0 | AE11: 58 | AF11: 44 | AG11: 11 | AH11: 1
A12: GENESIS | B12: =X11 -> zaqef-gadol | C12: =SUM(D12:K12) -> 175 | D12: =Z11 -> 0 | E12: =AA11 -> 0 | F12: =AB11 -> 62 | G12: =AC11 -> 0 | H12: =AD11 -> 0 | I12: =AE11 -> 58 | J12: =AF11 -> 44 | K12: =AG11 -> 11 | L12: =SUM(D12:K12)=Y11 -> TRUE | W12: GENESIS | X12: azla | Y12: 244 | Z12: 0 | AA12: 0 | AB12: 155 | AC12: 1 | AD12: 0 | AE12: 46 | AF12: 41 | AG12: 1 | AH12: 1
A13: GENESIS | B13: =X12 -> azla | C13: =SUM(D13:K13) -> 244 | D13: =Z12 -> 0 | E13: =AA12 -> 0 | F13: =AB12 -> 155 | G13: =AC12 -> 1 | H13: =AD12 -> 0 | I13: =AE12 -> 46 | J13: =AF12 -> 41 | K13: =AG12 -> 1 | L13: =SUM(D13:K13)=Y12 -> TRUE | W13: GENESIS | X13: qadma | Y13: 457 | Z13: 0 | AA13: 0 | AB13: 254 | AC13: 1 | AD13: 0 | AE13: 102 | AF13: 89 | AG13: 11 | AH13: 1
A14: GENESIS | B14: =X13 -> qadma | C14: =SUM(D14:K14) -> 457 | D14: =Z13 -> 0 | E14: =AA13 -> 0 | F14: =AB13 -> 254 | G14: =AC13 -> 1 | H14: =AD13 -> 0 | I14: =AE13 -> 102 | J14: =AF13 -> 89 | K14: =AG13 -> 11 | L14: =SUM(D14:K14)=Y13 -> TRUE | W14: GENESIS | X14: revia | Y14: 610 | Z14: 0 | AA14: 0 | AB14: 168 | AC14: 2 | AD14: 0 | AE14: 79 | AF14: 356 | AG14: 5 | AH14: 1
... A17: GENESIS | B17: =X16 -> zaqef-qatan | C17: =SUM(D17:K17) -> 1877 | D17: =Z16 -> 0 | E17: =AA16 -> 0 | F17: =AB16 -> 212 | G17: =AC16 -> 12 | H17: =AD16 -> 0 | I17: =AE16 -> 49 | J17: =AF16 -> 1224 | K17: =AG16 -> 380 | L17: =SUM(D17:K17)=Y16 -> TRUE | W17: EXODUS | X17: z-qatan tsinnor | Y17: 1 | Z17: 0 | AA17: 0 | AB17: 0 | AC17: 0 | AD17: 0 | AE17: 0 | AF17: 1 | AG17: 0 | AH17: 2
C18: =SUM(C3:C17) -> 5500 | D18: c | E18: d | F18: e | G18: f | H18: g | I18: A | J18: B | K18: C | W18: EXODUS | X18: pazer azla | Y18: 1 | Z18: 0 | AA18: 0 | AB18: 0 | AC18: 0 | AD18: 0 | AE18: 0 | AF18: 1 | AG18: 0 | AH18: 2
A19: EXODUS | B19: =X17 -> z-qatan tsinnor | C19: =SUM(D19:K19) -> 1 | D19: =Z17 -> 0 | E19: =AA17 -> 0 | F19: =AB17 -> 0 | G19: =AC17 -> 0 | H19: =AD17 -> 0 | I19: =AE17 -> 0 | J19: =AF17 -> 1 | K19: =AG17 -> 0 | L19: =SUM(D19:K19)=Y17 -> TRUE | W19: EXODUS | X19: pashta pashta | Y19: 1 | Z19: 0 | AA19: 0 | AB19: 1 | AC19: 0 | AD19: 0 | AE19: 0 | AF19: 0 | AG19: 0 | AH19: 2
A20: EXODUS | B20: =X18 -> pazer azla | C20: =SUM(D20:K20) -> 1 | D20: =Z18 -> 0 | E20: =AA18 -> 0 | F20: =AB18 -> 0 | G20: =AC18 -> 0 | H20: =AD18 -> 0 | I20: =AE18 -> 0 | J20: =AF18 -> 1 | K20: =AG18 -> 0 | L20: =SUM(D20:K20)=Y18 -> TRUE | W20: EXODUS | X20: z-qatan azla | Y20: 1 | Z20: 0 | AA20: 0 | AB20: 1 | AC20: 0 | AD20: 0 | AE20: 0 | AF20: 0 | AG20: 0 | AH20: 2
A21: EXODUS | B21: =X19 -> pashta pashta | C21: =SUM(D21:K21) -> 1 | D21: =Z19 -> 0 | E21: =AA19 -> 0 | F21: =AB19 -> 1 | G21: =AC19 -> 0 | H21: =AD19 -> 0 | I21: =AE19 -> 0 | J21: =AF19 -> 0 | K21: =AG19 -> 0 | L21: =SUM(D21:K21)=Y19 -> TRUE | W21: EXODUS | X21: azla pashta | Y21: 1 | Z21: 0 | AA21: 0 | AB21: 1 | AC21: 0 | AD21: 0 | AE21: 0 | AF21: 0 | AG21: 0 | AH21: 2
A22: EXODUS | B22: =X20 -> z-qatan azla | C22: =SUM(D22:K22) -> 1 | D22: =Z20 -> 0 | E22: =AA20 -> 0 | F22: =AB20 -> 1 | G22: =AC20 -> 0 | H22: =AD20 -> 0 | I22: =AE20 -> 0 | J22: =AF20 -> 0 | K22: =AG20 -> 0 | L22: =SUM(D22:K22)=Y20 -> TRUE | W22: EXODUS | X22: pazer z-qatan | Y22: 2 | Z22: 0 | AA22: 0 | AB22: 0 | AC22: 0 | AD22: 0 | AE22: 0 | AF22: 2 | AG22: 0 | AH22: 2
A23: EXODUS | B23: =X21 -> azla pashta | C23: =SUM(D23:K23) -> 1 | D23: =Z21 -> 0 | E23: =AA21 -> 0 | F23: =AB21 -> 1 | G23: =AC21 -> 0 | H23: =AD21 -> 0 | I23: =AE21 -> 0 | J23: =AF21 -> 0 | K23: =AG21 -> 0 | L23: =SUM(D23:K23)=Y21 -> TRUE | W23: EXODUS | X23: pazer | Y23: 29 | Z23: 0 | AA23: 0 | AB23: 18 | AC23: 0 | AD23: 0 | AE23: 5 | AF23: 5 | AG23: 1 | AH23: 2
A24: EXODUS | B24: =X22 -> pazer z-qatan | C24: =SUM(D24:K24) -> 2 | D24: =Z22 -> 0 | E24: =AA22 -> 0 | F24: =AB22 -> 0 | G24: =AC22 -> 0 | H24: =AD22 -> 0 | I24: =AE22 -> 0 | J24: =AF22 -> 2 | K24: =AG22 -> 0 | L24: =SUM(D24:K24)=Y22 -> TRUE | W24: EXODUS | X24: telisha-gedola | Y24: 44 | Z24: 0 | AA24: 0 | AB24: 12 | AC24: 0 | AD24: 0 | AE24: 10 | AF24: 22 | AG24: 0 | AH24: 2
A25: EXODUS | B25: =X23 -> pazer | C25: =SUM(D25:K25) -> 29 | D25: =Z23 -> 0 | E25: =AA23 -> 0 | F25: =AB23 -> 18 | G25: =AC23 -> 0 | H25: =AD23 -> 0 | I25: =AE23 -> 5 | J25: =AF23 -> 5 | K25: =AG23 -> 1 | L25: =SUM(D25:K25)=Y23 -> TRUE | W25: EXODUS | X25: tsinnor | Y25: 81 | Z25: 0 | AA25: 0 | AB25: 20 | AC25: 1 | AD25: 1 | AE25: 0 | AF25: 59 | AG25: 0 | AH25: 2
A26: EXODUS | B26: =X24 -> telisha-gedola | C26: =SUM(D26:K26) -> 44 | D26: =Z24 -> 0 | E26: =AA24 -> 0 | F26: =AB24 -> 12 | G26: =AC24 -> 0 | H26: =AD24 -> 0 | I26: =AE24 -> 10 | J26: =AF24 -> 22 | K26: =AG24 -> 0 | L26: =SUM(D26:K26)=Y24 -> TRUE | W26: EXODUS | X26: segol | Y26: 82 | Z26: 0 | AA26: 0 | AB26: 12 | AC26: 1 | AD26: 0 | AE26: 1 | AF26: 68 | AG26: 0 | AH26: 2
A27: EXODUS | B27: =X25 -> tsinnor | C27: =SUM(D27:K27) -> 81 | D27: =Z25 -> 0 | E27: =AA25 -> 0 | F27: =AB25 -> 20 | G27: =AC25 -> 1 | H27: =AD25 -> 1 | I27: =AE25 -> 0 | J27: =AF25 -> 59 | K27: =AG25 -> 0 | L27: =SUM(D27:K27)=Y25 -> TRUE | W27: EXODUS | X27: telisha-qetana | Y27: 90 | Z27: 0 | AA27: 2 | AB27: 45 | AC27: 1 | AD27: 0 | AE27: 17 | AF27: 24 | AG27: 1 | AH27: 2
A28: EXODUS | B28: =X26 -> segol | C28: =SUM(D28:K28) -> 82 | D28: =Z26 -> 0 | E28: =AA26 -> 0 | F28: =AB26 -> 12 | G28: =AC26 -> 1 | H28: =AD26 -> 0 | I28: =AE26 -> 1 | J28: =AF26 -> 68 | K28: =AG26 -> 0 | L28: =SUM(D28:K28)=Y26 -> TRUE | W28: EXODUS | X28: zaqef-gadol | Y28: 99 | Z28: 0 | AA28: 0 | AB28: 26 | AC28: 0 | AD28: 0 | AE28: 42 | AF28: 23 | AG28: 8 | AH28: 2
A29: EXODUS | B29: =X27 -> telisha-qetana | C29: =SUM(D29:K29) -> 90 | D29: =Z27 -> 0 | E29: =AA27 -> 2 | F29: =AB27 -> 45 | G29: =AC27 -> 1 | H29: =AD27 -> 0 | I29: =AE27 -> 17 | J29: =AF27 -> 24 | K29: =AG27 -> 1 | L29: =SUM(D29:K29)=Y27 -> TRUE | W29: EXODUS | X29: tarsin | Y29: 100 | Z29: 0 | AA29: 0 | AB29: 67 | AC29: 0 | AD29: 0 | AE29: 12 | AF29: 18 | AG29: 3 | AH29: 2
A30: EXODUS | B30: =X28 -> zaqef-gadol | C30: =SUM(D30:K30) -> 99 | D30: =Z28 -> 0 | E30: =AA28 -> 0 | F30: =AB28 -> 26 | G30: =AC28 -> 0 | H30: =AD28 -> 0 | I30: =AE28 -> 42 | J30: =AF28 -> 23 | K30: =AG28 -> 8 | L30: =SUM(D30:K30)=Y28 -> TRUE | W30: EXODUS | X30: azla | Y30: 229 | Z30: 0 | AA30: 0 | AB30: 139 | AC30: 0 | AD30: 2 | AE30: 49 | AF30: 35 | AG30: 4 | AH30: 2
... A36: EXODUS | B36: =X34 -> zaqef-qatan | C36: =SUM(D36:K36) -> 1477 | D36: =Z34 -> 0 | E36: =AA34 -> 0 | F36: =AB34 -> 195 | G36: =AC34 -> 14 | H36: =AD34 -> 0 | I36: =AE34 -> 49 | J36: =AF34 -> 920 | K36: =AG34 -> 299 | L36: =SUM(D36:K36)=Y34 -> TRUE | W36: LEVITICUS | X36: pazer | Y36: 27 | Z36: 0 | AA36: 0 | AB36: 12 | AC36: 0 | AD36: 0 | AE36: 8 | AF36: 7 | AG36: 0 | AH36: 3
C37: =SUM(C19:C36) -> 4494 | D37: c | E37: d | F37: e | G37: f | H37: g | I37: A | J37: B | K37: C | W37: LEVITICUS | X37: segol | Y37: 55 | Z37: 0 | AA37: 0 | AB37: 7 | AC37: 1 | AD37: 0 | AE37: 0 | AF37: 47 | AG37: 0 | AH37: 3
A38: LEVITICUS | B38: =X35 -> shalshelet | C38: =SUM(D38:K38) -> 1 | D38: =Z35 -> 0 | E38: =AA35 -> 0 | F38: =AB35 -> 1 | G38: =AC35 -> 0 | H38: =AD35 -> 0 | I38: =AE35 -> 0 | J38: =AF35 -> 0 | K38: =AG35 -> 0 | L38: =SUM(D38:K38)=Y35 -> TRUE | W38: LEVITICUS | X38: zaqef-gadol | Y38: 55 | Z38: 0 | AA38: 0 | AB38: 20 | AC38: 1 | AD38: 0 | AE38: 14 | AF38: 15 | AG38: 5 | AH38: 3
A39: LEVITICUS | B39: =X36 -> pazer | C39: =SUM(D39:K39) -> 27 | D39: =Z36 -> 0 | E39: =AA36 -> 0 | F39: =AB36 -> 12 | G39: =AC36 -> 0 | H39: =AD36 -> 0 | I39: =AE36 -> 8 | J39: =AF36 -> 7 | K39: =AG36 -> 0 | L39: =SUM(D39:K39)=Y36 -> TRUE | W39: LEVITICUS | X39: tsinnor | Y39: 56 | Z39: 0 | AA39: 0 | AB39: 16 | AC39: 2 | AD39: 0 | AE39: 0 | AF39: 38 | AG39: 0 | AH39: 3
A40: LEVITICUS | B40: =X37 -> segol | C40: =SUM(D40:K40) -> 55 | D40: =Z37 -> 0 | E40: =AA37 -> 0 | F40: =AB37 -> 7 | G40: =AC37 -> 1 | H40: =AD37 -> 0 | I40: =AE37 -> 0 | J40: =AF37 -> 47 | K40: =AG37 -> 0 | L40: =SUM(D40:K40)=Y37 -> TRUE | W40: LEVITICUS | X40: telisha-gedola | Y40: 57 | Z40: 0 | AA40: 0 | AB40: 24 | AC40: 0 | AD40: 0 | AE40: 12 | AF40: 19 | AG40: 2 | AH40: 3
A41: LEVITICUS | B41: =X38 -> zaqef-gadol | C41: =SUM(D41:K41) -> 55 | D41: =Z38 -> 0 | E41: =AA38 -> 0 | F41: =AB38 -> 20 | G41: =AC38 -> 1 | H41: =AD38 -> 0 | I41: =AE38 -> 14 | J41: =AF38 -> 15 | K41: =AG38 -> 5 | L41: =SUM(D41:K41)=Y38 -> TRUE | W41: LEVITICUS | X41: telisha-qetana | Y41: 71 | Z41: 0 | AA41: 0 | AB41: 39 | AC41: 0 | AD41: 0 | AE41: 10 | AF41: 22 | AG41: 0 | AH41: 3
A42: LEVITICUS | B42: =X39 -> tsinnor | C42: =SUM(D42:K42) -> 56 | D42: =Z39 -> 0 | E42: =AA39 -> 0 | F42: =AB39 -> 16 | G42: =AC39 -> 2 | H42: =AD39 -> 0 | I42: =AE39 -> 0 | J42: =AF39 -> 38 | K42: =AG39 -> 0 | L42: =SUM(D42:K42)=Y39 -> TRUE | W42: LEVITICUS | X42: tarsin | Y42: 76 | Z42: 0 | AA42: 0 | AB42: 48 | AC42: 0 | AD42: 0 | AE42: 11 | AF42: 15 | AG42: 2 | AH42: 3
A43: LEVITICUS | B43: =X40 -> telisha-gedola | C43: =SUM(D43:K43) -> 57 | D43: =Z40 -> 0 | E43: =AA40 -> 0 | F43: =AB40 -> 24 | G43: =AC40 -> 0 | H43: =AD40 -> 0 | I43: =AE40 -> 12 | J43: =AF40 -> 19 | K43: =AG40 -> 2 | L43: =SUM(D43:K43)=Y40 -> TRUE | W43: LEVITICUS | X43: azla | Y43: 175 | Z43: 0 | AA43: 0 | AB43: 110 | AC43: 0 | AD43: 0 | AE43: 27 | AF43: 35 | AG43: 2 | AH43: 3
A44: LEVITICUS | B44: =X41 -> telisha-qetana | C44: =SUM(D44:K44) -> 71 | D44: =Z41 -> 0 | E44: =AA41 -> 0 | F44: =AB41 -> 39 | G44: =AC41 -> 0 | H44: =AD41 -> 0 | I44: =AE41 -> 10 | J44: =AF41 -> 22 | K44: =AG41 -> 0 | L44: =SUM(D44:K44)=Y41 -> TRUE | W44: LEVITICUS | X44: revia | Y44: 313 | Z44: 0 | AA44: 0 | AB44: 96 | AC44: 0 | AD44: 0 | AE44: 20 | AF44: 197 | AG44: 0 | AH44: 3
A45: LEVITICUS | B45: =X42 -> tarsin | C45: =SUM(D45:K45) -> 76 | D45: =Z42 -> 0 | E45: =AA42 -> 0 | F45: =AB42 -> 48 | G45: =AC42 -> 0 | H45: =AD42 -> 0 | I45: =AE42 -> 11 | J45: =AF42 -> 15 | K45: =AG42 -> 2 | L45: =SUM(D45:K45)=Y42 -> TRUE | W45: LEVITICUS | X45: qadma | Y45: 334 | Z45: 0 | AA45: 0 | AB45: 182 | AC45: 0 | AD45: 0 | AE45: 70 | AF45: 76 | AG45: 6 | AH45: 3
A46: LEVITICUS | B46: =X43 -> azla | C46: 175 | D46: =Z43 -> 0 | E46: =AA43 -> 0 | F46: =AB43 -> 110 | G46: =AC43 -> 0 | H46: =AD43 -> 0 | I46: =AE43 -> 27 | J46: =AF43 -> 35 | K46: =AG43 -> 2 | L46: =SUM(D46:K46)=Y43 -> FALSE | W46: LEVITICUS | X46: pashta | Y46: 900 | Z46: 0 | AA46: 0 | AB46: 225 | AC46: 32 | AD46: 0 | AE46: 70 | AF46: 105 | AG46: 468 | AH46: 3
A47: LEVITICUS | B47: =X44 -> revia | C47: =SUM(D47:K47) -> 313 | D47: =Z44 -> 0 | E47: =AA44 -> 0 | F47: =AB44 -> 96 | G47: =AC44 -> 0 | H47: =AD44 -> 0 | I47: =AE44 -> 20 | J47: =AF44 -> 197 | K47: =AG44 -> 0 | L47: =SUM(D47:K47)=Y44 -> TRUE | W47: LEVITICUS | X47: zaqef-qatan | Y47: 987 | Z47: 0 | AA47: 0 | AB47: 131 | AC47: 12 | AD47: 0 | AE47: 30 | AF47: 612 | AG47: 202 | AH47: 3
...

Sheet Psalms-by-group
A1: Total ornaments for each note -- by mode
A2: Psalm totals by mode used
A3: book-seq | B3: Book | C3: degree | D3: shv mode | E3: pitch | F3: revia | G3: ole | H3: geresh | I3: illuy | J3: qadma | K3: pazer | L3: zarqa | M3: tsinnor | N3: shalshelet | O3: revia-mugrash
A4: 27 | B4: PSALMS | C4: 2 | D4: 1 | E4: D4 | F4: 2 | G4: 51 | H4: 0 | I4: 0 | J4: 0 | K4: 9 | L4: 2 | M4: 1 | N4: 0 | O4: 0
A5: 27 | B5: PSALMS | C5: 3 | D5: 1 | E5: E4 | F5: 122 | G5: 33 | H5: 22 | I5: 24 | J5: 29 | K5: 6 | L5: 24 | M5: 27 | N5: 1 | O5: 1
A6: 27 | B6: PSALMS | C6: 4 | D6: 1 | E6: F4 | F6: 233 | G6: 27 | H6: 171 | I6: 1 | J6: 7 | K6: 7 | L6: 4 | M6: 20 | N6: 0 | O6: 15
A7: 27 | B7: PSALMS | C7: 5 | D7: 1 | E7: G4 | F7: 3 | G7: 0 | H7: 0 | I7: 2 | J7: 2 | K7: 0 | L7: 0 | M7: 0 | N7: 0 | O7: 0
A8: 27 | B8: PSALMS | C8: 6 | D8: 1 | E8: A4 | F8: 315 | G8: 0 | H8: 322 | I8: 2 | J8: 2 | K8: 0 | L8: 1 | M8: 0 | N8: 5 | O8: 21
A9: 27 | B9: PSALMS | C9: 7 | D9: 1 | E9: B4 | F9: 0 | G9: 0 | H9: 0 | I9: 0 | J9: 0 | K9: 0 | L9: 0 | M9: 22 | N9: 0 | O9: 0
A10: 27 | B10: PSALMS | C10: 8 | D10: 1 | E10: C5 | F10: 68 | G10: 5 | H10: 0 | I10: 24 | J10: 56 | K10: 0 | L10: 15 | M10: 9 | N10: 1 | O10: 0
A11: book-seq | B11: Book | C11: degree | D11: shv mode | E11: pitch | F11: revia | G11: ole | H11: geresh | I11: illuy | J11: qadma | K11: pazer | L11: zarqa | M11: tsinnor | N11: shalshelet | O11: rev-mugr
A12: 27 | B12: PSALMS | C12: 2 | D12: 2 | E12: D4 | F12: 1 | G12: 25 | H12: 0 | I12: 1 | J12: 0 | K12: 5 | L12: 0 | M12: 1 | N12: 0 | O12: 0
A13: 27 | B13: PSALMS | C13: 3 | D13: 2 | E13: E4 | F13: 64 | G13: 8 | H13: 15 | I13: 13 | J13: 14 | K13: 4 | L13: 20 | M13: 13 | N13: 0 | O13: 0
A14: 27 | B14: PSALMS | C14: 4 | D14: 2 | E14: F4 | F14: 150 | G14: 8 | H14: 89 | I14: 1 | J14: 8 | K14: 1 | L14: 4 | M14: 5 | N14: 0 | O14: 6
A15: 27 | B15: PSALMS | C15: 5 | D15: 2 | E15: G4 | F15: 4 | G15: 0 | H15: 1 | I15: 0 | J15: 0 | K15: 0 | L15: 0 | M15: 0 | N15: 0 | O15: 0
A16: 27 | B16: PSALMS | C16: 6 | D16: 2 | E16: A4 | F16: 193 | G16: 0 | H16: 209 | I16: 1 | J16: 1 | K16: 0 | L16: 1 | M16: 0 | N16: 2 | O16: 18
A17: 27 | B17: PSALMS | C17: 7 | D17: 2 | E17: B4 | F17: 0 | G17: 1 | H17: 0 | I17: 0 | J17: 0 | K17: 0 | L17: 0 | M17: 2 | N17: 0 | O17: 0
A18: 27 | B18: PSALMS | C18: 8 | D18: 2 | E18: C5 | F18: 28 | G18: 1 | H18: 0 | I18: 10 | J18: 24 | K18: 1 | L18: 10 | M18: 5 | N18: 1 | O18: 0
A19: book-seq | B19: Book | C19: degree | D19: shv mode | E19: pitch | F19: revia | G19: ole | H19: geresh | I19: illuy | J19: qadma | K19: pazer | L19: zarqa | M19: tsinnor | N19: shalshelet | O19: rev-mugr
A20: 27 | B20: PSALMS | C20: 2 | D20: 3 | E20: D4 | F20: 1 | G20: 51 | H20: 0 | I20: 1 | J20: 1 | K20: 12 | L20: 3 | M20: 3 | N20: 0 | O20: 0
A21: 27 | B21: PSALMS | C21: 3 | D21: 3 | E21: E4 | F21: 116 | G21: 46 | H21: 19 | I21: 22 | J21: 32 | K21: 9 | L21: 28 | M21: 22 | N21: 1 | O21: 1
A22: 27 | B22: PSALMS | C22: 4 | D22: 3 | E22: F4 | F22: 252 | G22: 32 | H22: 162 | I22: 2 | J22: 4 | K22: 4 | L22: 8 | M22: 18 | N22: 1 | O22: 17
A23: 27 | B23: PSALMS | C23: 5 | D23: 3 | E23: G4 | F23: 4 | G23: 0 | H23: 0 | I23: 1 | J23: 1 | K23: 0 | L23: 1 | M23: 0 | N23: 0 | O23: 0
A24: 27 | B24: PSALMS | C24: 6 | D24: 3 | E24: A4 | F24: 306 | G24: 0 | H24: 325 | I24: 1 | J24: 5 | K24: 0 | L24: 7 | M24: 0 | N24: 6 | O24: 35
A25: 27 | B25: PSALMS | C25: 7 | D25: 3 | E25: B4 | F25: 0 | G25: 0 | H25: 0 | I25: 0 | J25: 0 | K25: 0 | L25: 0 | M25: 22 | N25: 0 | O25: 0
A26: 27 | B26: PSALMS | C26: 8 | D26: 3 | E26: C5 | F26: 68 | G26: 6 | H26: 1 | I26: 21 | J26: 65 | K26: 4 | L26: 12 | M26: 18 | N26: 1 | O26: 0
A27: book-seq | B27: Book | C27: degree | D27: shv mode | E27: pitch | F27: revia | G27: ole | H27: geresh | I27: illuy | J27: qadma | K27: pazer | L27: zarqa | M27: tsinnor | N27: shalshelet | O27: rev-mugr
A28: 27 | B28: PSALMS | C28: 2 | D28: 4 | E28: D4 | F28: 0 | G28: 22 | H28: 0 | I28: 0 | J28: 0 | K28: 2 | L28: 0 | M28: 0 | N28: 0 | O28: 0
A29: 27 | B29: PSALMS | C29: 3 | D29: 4 | E29: E4 | F29: 47 | G29: 12 | H29: 7 | I29: 9 | J29: 8 | K29: 3 | L29: 5 | M29: 9 | N29: 0 | O29: 1
A30: 27 | B30: PSALMS | C30: 4 | D30: 4 | E30: F4 | F30: 78 | G30: 5 | H30: 63 | I30: 0 | J30: 4 | K30: 1 | L30: 0 | M30: 6 | N30: 0 | O30: 8
A31: 27 | B31: PSALMS | C31: 5 | D31: 4 | E31: G4 | F31: 3 | G31: 0 | H31: 0 | I31: 0 | J31: 0 | K31: 0 | L31: 0 | M31: 0 | N31: 0 | O31: 0
A32: 27 | B32: PSALMS | C32: 6 | D32: 4 | E32: A4 | F32: 77 | G32: 0 | H32: 80 | I32: 0 | J32: 2 | K32: 0 | L32: 2 | M32: 0 | N32: 5 | O32: 9
A33: 27 | B33: PSALMS | C33: 7 | D33: 4 | E33: B4 | F33: 0 | G33: 0 | H33: 0 | I33: 0 | J33: 0 | K33: 0 | L33: 0 | M33: 11 | N33: 0 | O33: 0
A34: 27 | B34: PSALMS | C34: 8 | D34: 4 | E34: C5 | F34: 13 | G34: 3 | H34: 0 | I34: 9 | J34: 15 | K34: 2 | L34: 4 | M34: 3 | N34: 1 | O34: 0
A35: book-seq | B35: Book | C35: degree | D35: shv mode | E35: pitch | F35: revia | G35: ole | H35: geresh | I35: illuy | J35: qadma | K35: pazer | L35: zarqa | M35: tsinnor | N35: shalshelet | O35: rev-mugr
A36: 27 | B36: PSALMS | C36: 2 | D36: 7 | E36: D4 | F36: 1 | G36: 1 | H36: 0 | I36: 1 | J36: 0 | K36: 1 | L36: 0 | M36: 0 | N36: 0 | O36: 0
A37: 27 | B37: PSALMS | C37: 3 | D37: 7 | E37: E4 | F37: 10 | G37: 3 | H37: 1 | I37: 4 | J37: 1 | K37: 1 | L37: 4 | M37: 0 | N37: 2 | O37: 0
A38: 27 | B38: PSALMS | C38: 4 | D38: 7 | E38: F4 | F38: 19 | G38: 1 | H38: 12 | I38: 0 | J38: 1 | K38: 0 | L38: 1 | M38: 0 | N38: 0 | O38: 1
A39: 27 | B39: PSALMS | C39: 6 | D39: 7 | E39: A4 | F39: 24 | G39: 0 | H39: 24 | I39: 0 | J39: 0 | K39: 0 | L39: 0 | M39: 0 | N39: 2 | O39: 5
A40: 27 | B40: PSALMS | C40: 7 | D40: 7 | E40: B4 | F40: 0 | G40: 0 | H40: 0 | I40: 0 | J40: 0 | K40: 0 | L40: 0 | M40: 2 | N40: 0 | O40: 0
...

Sheet The Five Scrolls
A1: book seq | B1: book | C1: degree | D1: note | E1: Revia | F1: Azla | G1: Zaqef-qatan | H1: Zaqef-gadol | I1: Pashta | J1: Telisha-gedola | K1: Telisha-qetana | L1: Qarne | M1: Tsinnor | N1: Segol | O1: Tarsin | P1: Qadma | Q1: Pazer | R1: Shalshelet
A2: 30 | B2: SONG | C2: 3 | D2: E4 | E2: 8 | F2: 4 | G2: 25 | H2: 3 | I2: 62 | J2: 0 | K2: 0 | L2: 0 | M2: 0 | N2: 0 | O2: 3 | P2: 9 | Q2: 0 | R2: 0 | S2: =SUM(E2:R2) -> 114
A3: 30 | B3: SONG | C3: 4 | D3: F4 | E3: 0 | F3: 0 | G3: 4 | H3: 0 | I3: 8 | J3: 0 | K3: 0 | L3: 0 | M3: 0 | N3: 0 | O3: 0 | P3: 0 | Q3: 0 | R3: 0 | S3: =SUM(E3:R3) -> 12
A4: 30 | B4: SONG | C4: 6 | D4: A4 | E4: 3 | F4: 4 | G4: 6 | H4: 3 | I4: 20 | J4: 0 | K4: 1 | L4: 0 | M4: 0 | N4: 0 | O4: 0 | P4: 3 | Q4: 0 | R4: 0 | S4: =SUM(E4:R4) -> 40
A5: 30 | B5: SONG | C5: 7 | D5: B4 | E5: 14 | F5: 0 | G5: 96 | H5: 1 | I5: 18 | J5: 0 | K5: 0 | L5: 0 | M5: 1 | N5: 1 | O5: 1 | P5: 0 | Q5: 0 | R5: 0 | S5: =SUM(E5:R5) -> 132
A6: 30 | B6: SONG | C6: 8 | D6: C5 | E6: 0 | F6: 0 | G6: 37 | H6: 0 | I6: 77 | J6: 0 | K6: 0 | L6: 0 | M6: 0 | N6: 0 | O6: 0 | P6: 0 | Q6: 0 | R6: 0 | S6: =SUM(E6:R6) -> 114
A7: book seq | B7: book | C7: degree | D7: note | E7: Revia | F7: Azla | G7: Zaqef-qatan | H7: Zaqef-gadol | I7: Pashta | J7: Telisha-gedola | K7: Telisha-qetana | L7: Qarne | M7: Tsinnor | N7: Segol | O7: Tarsin | P7: Qadma | Q7: Pazer | R7: Shalshelet | S7: =SUM(S2:S6) -> 412 | T7: =S7=Prose!C374 -> TRUE
A8: 31 | B8: RUTH | C8: 3 | D8: E4 | E8: 14 | F8: 12 | G8: 20 | H8: 2 | I8: 35 | J8: 2 | K8: 8 | L8: 0 | M8: 1 | N8: 0 | O8: 3 | P8: 18 | Q8: 1 | R8: 0 | S8: =SUM(E8:R8) -> 116
A9: 31 | B9: RUTH | C9: 4 | D9: F4 | E9: 0 | F9: 0 | G9: 5 | H9: 0 | I9: 11 | J9: 0 | K9: 0 | L9: 0 | M9: 0 | N9: 0 | O9: 0 | P9: 1 | Q9: 0 | R9: 0 | S9: =SUM(E9:R9) -> 17
A10: 31 | B10: RUTH | C10: 6 | D10: A4 | E10: 10 | F10: 4 | G10: 4 | H10: 2 | I10: 13 | J10: 2 | K10: 3 | L10: 0 | M10: 0 | N10: 0 | O10: 2 | P10: 9 | Q10: 0 | R10: 0 | S10: =SUM(E10:R10) -> 49
A11: 31 | B11: RUTH | C11: 7 | D11: B4 | E11: 23 | F11: 3 | G11: 78 | H11: 3 | I11: 11 | J11: 2 | K11: 2 | L11: 0 | M11: 1 | N11: 2 | O11: 0 | P11: 6 | Q11: 0 | R11: 0 | S11: =SUM(E11:R11) -> 131
A12: 31 | B12: RUTH | C12: 8 | D12: C5 | E12: 1 | F12: 0 | G12: 31 | H12: 1 | I12: 72 | J12: 0 | K12: 0 | L12: 0 | M12: 0 | N12: 0 | O12: 0 | P12: 2 | Q12: 0 | R12: 0 | S12: =SUM(E12:R12) -> 107
A13: book seq | B13: book | C13: degree | D13: note | E13: Revia | F13: Azla | G13: Zaqef-qatan | H13: Zaqef-gadol | I13: Pashta | J13: Telisha-gedola | K13: Telisha-qetana | L13: Qarne | M13: Tsinnor | N13: Segol | O13: Tarsin | P13: Qadma | Q13: Pazer | R13: Shalshelet | S13: =SUM(S8:S12) -> 420 | T13: =S13=Prose!C387 -> TRUE
A14: 32 | B14: LAMENTATIONS | C14: 3 | D14: E4 | E14: 10 | F14: 7 | G14: 31 | H14: 0 | I14: 59 | J14: 0 | K14: 3 | L14: 0 | M14: 0 | N14: 0 | O14: 2 | P14: 25 | Q14: 0 | R14: 0 | S14: =SUM(E14:R14) -> 137
A15: 32 | B15: LAMENTATIONS | C15: 4 | D15: F4 | E15: 0 | F15: 0 | G15: 2 | H15: 0 | I15: 3 | J15: 0 | K15: 0 | L15: 0 | M15: 0 | N15: 0 | O15: 0 | P15: 0 | Q15: 0 | R15: 0 | S15: =SUM(E15:R15) -> 5
A16: 32 | B16: LAMENTATIONS | C16: 6 | D16: A4 | E16: 0 | F16: 0 | G16: 4 | H16: 0 | I16: 14 | J16: 0 | K16: 0 | L16: 0 | M16: 0 | N16: 0 | O16: 0 | P16: 4 | Q16: 0 | R16: 0 | S16: =SUM(E16:R16) -> 22
A17: 32 | B17: LAMENTATIONS | C17: 7 | D17: B4 | E17: 16 | F17: 0 | G17: 102 | H17: 1 | I17: 14 | J17: 1 | K17: 0 | L17: 0 | M17: 1 | N17: 1 | O17: 1 | P17: 1 | Q17: 0 | R17: 0 | S17: =SUM(E17:R17) -> 138
A18: 32 | B18: LAMENTATIONS | C18: 8 | D18: C5 | E18: 0 | F18: 1 | G18: 60 | H18: 0 | I18: 126 | J18: 0 | K18: 0 | L18: 0 | M18: 0 | N18: 0 | O18: 0 | P18: 1 | Q18: 0 | R18: 0 | S18: =SUM(E18:R18) -> 188
A19: book seq | B19: book | C19: degree | D19: note | E19: Revia | F19: Azla | G19: Zaqef-qatan | H19: Zaqef-gadol | I19: Pashta | J19: Telisha-gedola | K19: Telisha-qetana | L19: Qarne | M19: Tsinnor | N19: Segol | O19: Tarsin | P19: Qadma | Q19: Pazer | R19: Shalshelet | S19: =SUM(S14:S18) -> 490 | T19: =S19=Prose!C399 -> TRUE
A20: 33 | B20: QOHELET | C20: 3 | D20: E4 | E20: 20 | F20: 16 | G20: 43 | H20: 6 | I20: 73 | J20: 7 | K20: 6 | L20: 0 | M20: 2 | N20: 0 | O20: 3 | P20: 29 | Q20: 3 | R20: 0 | S20: =SUM(E20:R20) -> 208
A21: 33 | B21: QOHELET | C21: 4 | D21: F4 | E21: 0 | F21: 0 | G21: 4 | H21: 0 | I21: 16 | J21: 0 | K21: 0 | L21: 0 | M21: 0 | N21: 0 | O21: 0 | P21: 2 | Q21: 0 | R21: 0 | S21: =SUM(E21:R21) -> 22
A22: 33 | B22: QOHELET | C22: 6 | D22: A4 | E22: 6 | F22: 3 | G22: 5 | H22: 8 | I22: 21 | J22: 0 | K22: 3 | L22: 0 | M22: 0 | N22: 0 | O22: 8 | P22: 11 | Q22: 1 | R22: 0 | S22: =SUM(E22:R22) -> 66
A23: 33 | B23: QOHELET | C23: 7 | D23: B4 | E23: 36 | F23: 8 | G23: 185 | H23: 3 | I23: 13 | J23: 2 | K23: 7 | L23: 0 | M23: 0 | N23: 2 | O23: 3 | P23: 15 | Q23: 2 | R23: 0 | S23: =SUM(E23:R23) -> 276
A24: 33 | B24: QOHELET | C24: 8 | D24: C5 | E24: 1 | F24: 0 | G24: 32 | H24: 1 | I24: 120 | J24: 0 | K24: 0 | L24: 0 | M24: 0 | N24: 0 | O24: 0 | P24: 1 | Q24: 0 | R24: 0 | S24: =SUM(E24:R24) -> 155
A25: book seq | B25: book | C25: degree | D25: note | E25: Revia | F25: Azla | G25: Zaqef-qatan | H25: Zaqef-gadol | I25: Pashta | J25: Telisha-gedola | K25: Telisha-qetana | L25: Qarne | M25: Tsinnor | N25: Segol | O25: Tarsin | P25: Qadma | Q25: Pazer | R25: Shalshelet | S25: =SUM(S20:S24) -> 727 | T25: =S25=Prose!C412 -> TRUE
A26: 34 | B26: ESTHER | C26: 2 | D26: D4 | E26: 0 | F26: 0 | G26: 0 | H26: 0 | I26: 0 | J26: 0 | K26: 0 | L26: 1 | M26: 0 | N26: 0 | O26: 0 | P26: 0 | Q26: 0 | R26: 0 | S26: =SUM(E26:R26) -> 1
A27: 34 | B27: ESTHER | C27: 3 | D27: E4 | E27: 21 | F27: 40 | G27: 24 | H27: 4 | I27: 41 | J27: 12 | K27: 17 | L27: 0 | M27: 5 | N27: 3 | O27: 13 | P27: 53 | Q27: 4 | R27: 0 | S27: =SUM(E27:R27) -> 237
A28: 34 | B28: ESTHER | C28: 4 | D28: F4 | E28: 0 | F28: 0 | G28: 3 | H28: 0 | I28: 5 | J28: 0 | K28: 0 | L28: 0 | M28: 0 | N28: 0 | O28: 0 | P28: 1 | Q28: 0 | R28: 0 | S28: =SUM(E28:R28) -> 9
A29: 34 | B29: ESTHER | C29: 6 | D29: A4 | E29: 16 | F29: 11 | G29: 6 | H29: 5 | I29: 19 | J29: 3 | K29: 6 | L29: 0 | M29: 0 | N29: 0 | O29: 8 | P29: 26 | Q29: 1 | R29: 0 | S29: =SUM(E29:R29) -> 101
A30: 34 | B30: ESTHER | C30: 7 | D30: B4 | E30: 83 | F30: 16 | G30: 196 | H30: 5 | I30: 45 | J30: 10 | K30: 15 | L30: 0 | M30: 8 | N30: 10 | O30: 6 | P30: 31 | Q30: 12 | R30: 0 | S30: =SUM(E30:R30) -> 437
A31: 34 | B31: ESTHER | C31: 8 | D31: C5 | E31: 0 | F31: 0 | G31: 55 | H31: 2 | I31: 167 | J31: 3 | K31: 0 | L31: 0 | M31: 0 | N31: 0 | O31: 1 | P31: 2 | Q31: 0 | R31: 0 | S31: =SUM(E31:R31) -> 230
S32: =SUM(S26:S31) -> 1015 | T32: =S32=Prose!C426 -> TRUE

Sheet Torah
A1: book seq | B1: book | C1: degree | D1: note | E1: Revia | F1: Azla | G1: Zaqef-qatan | H1: Zaqef-gadol | I1: Pashta | J1: Telisha-gedola | K1: Telisha-qetana | L1: Qarne | M1: Tsinnor | N1: Segol | O1: Tarsin | P1: Qadma | Q1: Pazer | R1: Shalshelet
A2: 1 | B2: GENESIS | C2: 3 | D2: E4 | E2: 168 | F2: 155 | G2: 212 | H2: 62 | I2: 401 | J2: 29 | K2: 48 | L2: 0 | M2: 19 | N2: 11 | O2: 66 | P2: 254 | Q2: 15 | R2: 3 | S2: =SUM(E2:R2) -> 1443
A3: 1 | B3: GENESIS | C3: 4 | D3: F4 | E3: 2 | F3: 1 | G3: 12 | H3: 0 | I3: 35 | J3: 0 | K3: 0 | L3: 0 | M3: 1 | N3: 0 | O3: 0 | P3: 1 | Q3: 0 | R3: 0 | S3: =SUM(E3:R3) -> 52
A4: 1 | B4: GENESIS | C4: 5 | D4: G4 | E4: 0 | F4: 0 | G4: 0 | H4: 0 | I4: 1 | J4: 0 | K4: 0 | L4: 0 | M4: 0 | N4: 0 | O4: 0 | P4: 0 | Q4: 0 | R4: 0 | S4: =SUM(E4:R4) -> 1
A5: 1 | B5: GENESIS | C5: 6 | D5: A4 | E5: 79 | F5: 46 | G5: 49 | H5: 58 | I5: 201 | J5: 8 | K5: 19 | L5: 0 | M5: 0 | N5: 0 | O5: 29 | P5: 102 | Q5: 5 | R5: 0 | S5: =SUM(E5:R5) -> 596
A6: 1 | B6: GENESIS | C6: 7 | D6: B4 | E6: 356 | F6: 41 | G6: 1224 | H6: 44 | I6: 186 | J6: 15 | K6: 24 | L6: 0 | M6: 53 | N6: 61 | O6: 18 | P6: 89 | Q6: 9 | R6: 0 | S6: =SUM(E6:R6) -> 2120
A7: 1 | B7: GENESIS | C7: 8 | D7: C5 | E7: 5 | F7: 1 | G7: 380 | H7: 11 | I7: 876 | J7: 0 | K7: 2 | L7: 0 | M7: 0 | N7: 0 | O7: 0 | P7: 11 | Q7: 0 | R7: 0 | S7: =SUM(E7:R7) -> 1286
A8: book seq | B8: book | C8: degree | D8: note | E8: Revia | F8: Azla | G8: Zaqef-qatan | H8: Zaqef-gadol | I8: Pashta | J8: Telisha-gedola | K8: Telisha-qetana | L8: Qarne | M8: Tsinnor | N8: Segol | O8: Tarsin | P8: Qadma | Q8: Pazer | R8: Shalshelet | S8: =SUM(S2:S7) -> 5498 | T8: missing 2 composite
A9: 2 | B9: EXODUS | C9: 2 | D9: D4 | E9: 0 | F9: 0 | G9: 0 | H9: 0 | I9: 0 | J9: 0 | K9: 2 | L9: 0 | M9: 0 | N9: 0 | O9: 0 | P9: 0 | Q9: 0 | R9: 0 | S9: =SUM(E9:R9) -> 2
A10: 2 | B10: EXODUS | C10: 3 | D10: E4 | E10: 140 | F10: 139 | G10: 195 | H10: 26 | I10: 301 | J10: 12 | K10: 45 | L10: 0 | M10: 20 | N10: 12 | O10: 67 | P10: 215 | Q10: 18 | R10: 0 | S10: =SUM(E10:R10) -> 1190
A11: 2 | B11: EXODUS | C11: 4 | D11: F4 | E11: 0 | F11: 0 | G11: 14 | H11: 0 | I11: 40 | J11: 0 | K11: 1 | L11: 0 | M11: 1 | N11: 1 | O11: 0 | P11: 2 | Q11: 0 | R11: 0 | S11: =SUM(E11:R11) -> 59
A12: 2 | B12: EXODUS | C12: 5 | D12: G4 | E12: 0 | F12: 2 | G12: 0 | H12: 0 | I12: 4 | J12: 0 | K12: 0 | L12: 0 | M12: 1 | N12: 0 | O12: 0 | P12: 1 | Q12: 0 | R12: 0 | S12: =SUM(E12:R12) -> 8
A13: 2 | B13: EXODUS | C13: 6 | D13: A4 | E13: 56 | F13: 49 | G13: 49 | H13: 42 | I13: 128 | J13: 10 | K13: 17 | L13: 0 | M13: 0 | N13: 1 | O13: 12 | P13: 101 | Q13: 5 | R13: 0 | S13: =SUM(E13:R13) -> 470
A14: 2 | B14: EXODUS | C14: 7 | D14: B4 | E14: 310 | F14: 35 | G14: 920 | H14: 23 | I14: 159 | J14: 22 | K14: 24 | L14: 0 | M14: 59 | N14: 68 | O14: 18 | P14: 80 | Q14: 5 | R14: 0 | S14: =SUM(E14:R14) -> 1723
A15: 2 | B15: EXODUS | C15: 8 | D15: C5 | E15: 1 | F15: 4 | G15: 299 | H15: 8 | I15: 707 | J15: 0 | K15: 1 | L15: 0 | M15: 0 | N15: 0 | O15: 3 | P15: 11 | Q15: 1 | R15: 0 | S15: =SUM(E15:R15) -> 1035
A16: book seq | B16: book | C16: degree | D16: note | E16: Revia | F16: Azla | G16: Zaqef-qatan | H16: Zaqef-gadol | I16: Pashta | J16: Telisha-gedola | K16: Telisha-qetana | L16: Qarne | M16: Tsinnor | N16: Segol | O16: Tarsin | P16: Qadma | Q16: Pazer | R16: Shalshelet | S16: =SUM(S9:S15) -> 4487
A17: 3 | B17: LEVITICUS | C17: 3 | D17: E4 | E17: 96 | F17: 110 | G17: 131 | H17: 20 | I17: 225 | J17: 24 | K17: 39 | L17: 0 | M17: 16 | N17: 7 | O17: 48 | P17: 182 | Q17: 12 | R17: 1 | S17: =SUM(E17:R17) -> 911
A18: 3 | B18: LEVITICUS | C18: 4 | D18: F4 | E18: 0 | F18: 0 | G18: 12 | H18: 1 | I18: 32 | J18: 0 | K18: 0 | L18: 0 | M18: 2 | N18: 1 | O18: 0 | P18: 0 | Q18: 0 | R18: 0 | S18: =SUM(E18:R18) -> 48
A19: 3 | B19: LEVITICUS | C19: 6 | D19: A4 | E19: 20 | F19: 28 | G19: 30 | H19: 14 | I19: 70 | J19: 12 | K19: 10 | L19: 0 | M19: 0 | N19: 0 | O19: 11 | P19: 70 | Q19: 8 | R19: 0 | S19: =SUM(E19:R19) -> 273
A20: 3 | B20: LEVITICUS | C20: 7 | D20: B4 | E20: 197 | F20: 35 | G20: 612 | H20: 15 | I20: 105 | J20: 19 | K20: 22 | L20: 0 | M20: 38 | N20: 47 | O20: 15 | P20: 76 | Q20: 7 | R20: 0 | S20: =SUM(E20:R20) -> 1188
A21: 3 | B21: LEVITICUS | C21: 8 | D21: C5 | E21: 0 | F21: 2 | G21: 202 | H21: 5 | I21: 468 | J21: 2 | K21: 0 | L21: 0 | M21: 0 | N21: 0 | O21: 2 | P21: 6 | Q21: 0 | R21: 0 | S21: =SUM(E21:R21) -> 687
A22: book seq | B22: book | C22: degree | D22: note | E22: Revia | F22: Azla | G22: Zaqef-qatan | H22: Zaqef-gadol | I22: Pashta | J22: Telisha-gedola | K22: Telisha-qetana | L22: Qarne | M22: Tsinnor | N22: Segol | O22: Tarsin | P22: Qadma | Q22: Pazer | R22: Shalshelet | S22: =SUM(S17:S21) -> 3107 | T22: =S22=Prose!C51 -> TRUE
A23: 4 | B23: NUMBERS | C23: 2 | D23: D4 | E23: 0 | F23: 1 | G23: 0 | H23: 0 | I23: 0 | J23: 0 | K23: 1 | L23: 1 | M23: 0 | N23: 0 | O23: 0 | P23: 1 | Q23: 0 | R23: 0 | S23: =SUM(E23:R23) -> 4
A24: 4 | B24: NUMBERS | C24: 3 | D24: E4 | E24: 134 | F24: 146 | G24: 206 | H24: 46 | I24: 304 | J24: 14 | K24: 43 | L24: 0 | M24: 19 | N24: 11 | O24: 66 | P24: 236 | Q24: 14 | R24: 0 | S24: =SUM(E24:R24) -> 1239
A25: 4 | B25: NUMBERS | C25: 4 | D25: F4 | E25: 0 | F25: 0 | G25: 21 | H25: 1 | I25: 51 | J25: 0 | K25: 0 | L25: 0 | M25: 5 | N25: 1 | O25: 0 | P25: 1 | Q25: 0 | R25: 0 | S25: =SUM(E25:R25) -> 80
A26: 4 | B26: NUMBERS | C26: 6 | D26: A4 | E26: 58 | F26: 36 | G26: 44 | H26: 46 | I26: 131 | J26: 15 | K26: 15 | L26: 0 | M26: 0 | N26: 0 | O26: 14 | P26: 96 | Q26: 1 | R26: 0 | S26: =SUM(E26:R26) -> 456
A27: 4 | B27: NUMBERS | C27: 7 | D27: B4 | E27: 302 | F27: 40 | G27: 807 | H27: 29 | I27: 134 | J27: 21 | K27: 29 | L27: 0 | M27: 72 | N27: 84 | O27: 32 | P27: 95 | Q27: 21 | R27: 0 | S27: =SUM(E27:R27) -> 1666
A28: 4 | B28: NUMBERS | C28: 8 | D28: C5 | E28: 3 | F28: 0 | G28: 280 | H28: 4 | I28: 598 | J28: 0 | K28: 0 | L28: 0 | M28: 0 | N28: 0 | O28: 2 | P28: 6 | Q28: 0 | R28: 0 | S28: =SUM(E28:R28) -> 893
A29: book seq | B29: book | C29: degree | D29: note | E29: Revia | F29: Azla | G29: Zaqef-qatan | H29: Zaqef-gadol | I29: Pashta | J29: Telisha-gedola | K29: Telisha-qetana | L29: Qarne | M29: Tsinnor | N29: Segol | O29: Tarsin | P29: Qadma | Q29: Pazer | R29: Shalshelet | S29: =SUM(S23:S28) -> 4338 | T29: =S29=Prose!C65 -> TRUE
A30: 5 | B30: DEUTERONOMY | C30: 2 | D30: D4 | E30: 0 | F30: 0 | G30: 0 | H30: 0 | I30: 0 | J30: 0 | K30: 1 | L30: 0 | M30: 0 | N30: 0 | O30: 0 | P30: 1 | Q30: 0 | R30: 0 | S30: =SUM(E30:R30) -> 2
A31: 5 | B31: DEUTERONOMY | C31: 3 | D31: E4 | E31: 144 | F31: 141 | G31: 176 | H31: 23 | I31: 263 | J31: 26 | K31: 57 | L31: 0 | M31: 19 | N31: 10 | O31: 63 | P31: 219 | Q31: 15 | R31: 0 | S31: =SUM(E31:R31) -> 1156
A32: 5 | B32: DEUTERONOMY | C32: 4 | D32: F4 | E32: 0 | F32: 0 | G32: 12 | H32: 0 | I32: 45 | J32: 0 | K32: 2 | L32: 0 | M32: 5 | N32: 3 | O32: 0 | P32: 1 | Q32: 0 | R32: 0 | S32: =SUM(E32:R32) -> 68
A33: 5 | B33: DEUTERONOMY | C33: 5 | D33: G4 | E33: 0 | F33: 1 | G33: 0 | H33: 0 | I33: 3 | J33: 0 | K33: 0 | L33: 0 | M33: 1 | N33: 0 | O33: 0 | P33: 2 | Q33: 0 | R33: 0 | S33: =SUM(E33:R33) -> 7
A34: 5 | B34: DEUTERONOMY | C34: 6 | D34: A4 | E34: 51 | F34: 40 | G34: 33 | H34: 18 | I34: 144 | J34: 7 | K34: 17 | L34: 0 | M34: 0 | N34: 1 | O34: 28 | P34: 83 | Q34: 3 | R34: 0 | S34: =SUM(E34:R34) -> 425
A35: 5 | B35: DEUTERONOMY | C35: 7 | D35: B4 | E35: 309 | F35: 61 | G35: 826 | H35: 23 | I35: 135 | J35: 33 | K35: 40 | L35: 0 | M35: 42 | N35: 55 | O35: 16 | P35: 130 | Q35: 15 | R35: 0 | S35: =SUM(E35:R35) -> 1685
A36: 5 | B36: DEUTERONOMY | C36: 8 | D36: C5 | E36: 5 | F36: 1 | G36: 241 | H36: 6 | I36: 627 | J36: 1 | K36: 0 | L36: 0 | M36: 0 | N36: 0 | O36: 1 | P36: 5 | Q36: 0 | R36: 0 | S36: =SUM(E36:R36) -> 887
S37: =SUM(S30:S36) -> 4230 | T37: missing 8 composite
G38: Zaqef-qatan | I38: Pashta
B39: =B6 -> GENESIS | C39: =C6 -> 7 | D39: =D6 -> B4 | E39: =E6 -> 356 | F39: =F6 -> 41 | G39: =G6 -> 1224 | H39: =H6 -> 44 | I39: =I6 -> 186 | ... R39: =R6 -> 0
B40: =B7 -> GENESIS | C40: =C7 -> 8 | D40: =D7 -> C5 | E40: =E7 -> 5 | F40: =F7 -> 1 | G40: =G7 -> 380 | H40: =H7 -> 11 | I40: =I7 -> 876 | ... R40: =R7 -> 0
...

Sheet Joshua-Judges
A1: book seq | B1: book | C1: degree | D1: note | E1: Revia | F1: Azla | G1: Zaefq-qatan | H1: Zaqef-gadol | I1: Pashta | J1: Telisha-gedola | K1: Telisha-qetana | L1: Qarne | M1: Tsinnor | N1: Segol | O1: Qadma | P1: Shalshelet
A2: 6 | B2: JOSHUA | C2: 2 | D2: D4 | E2: 0 | F2: 0 | G2: 0 | H2: 0 | I2: 0 | J2: 0 | K2: 0 | L2: 1 | M2: 0 | N2: 0 | O2: 0 | P2: 0
A3: 6 | B3: JOSHUA | C3: 3 | D3: E4 | E3: 100 | F3: 127 | G3: 103 | H3: 13 | I3: 195 | J3: 33 | K3: 46 | L3: 0 | M3: 4 | N3: 3 | O3: 181 | P3: 0
A4: 6 | B4: JOSHUA | C4: 4 | D4: F4 | E4: 1 | F4: 1 | G4: 10 | H4: 0 | I4: 31 | J4: 0 | K4: 0 | L4: 0 | M4: 6 | N4: 3 | O4: 1 | P4: 0
A5: 6 | B5: JOSHUA | C5: 6 | D5: A4 | E5: 43 | F5: 47 | G5: 15 | H5: 12 | I5: 61 | J5: 13 | K5: 21 | L5: 0 | M5: 0 | N5: 0 | O5: 87 | P5: 0
A6: 6 | B6: JOSHUA | C6: 7 | D6: B4 | E6: 216 | F6: 50 | G6: 530 | H6: 20 | I6: 109 | J6: 28 | K6: 40 | L6: 0 | M6: 27 | N6: 30 | O6: 96 | P6: 0
A7: 6 | B7: JOSHUA | C7: 8 | D7: C5 | E7: 3 | F7: 2 | G7: 214 | H7: 4 | I7: 484 | J7: 1 | K7: 1 | L7: 0 | M7: 0 | N7: 0 | O7: 6 | P7: 0
A8: book seq | B8: book | C8: degree | D8: note | E8: Revia | F8: Azla | G8: Zaqef-qatan | H8: Zaqef-gadol | I8: Pashta | J8: Telisha-gedola | K8: Telisha-qetana | L8: Qarne | M8: Tsinnor | N8: Segol | O8: Qadma | P8: Shalshelet
A9: 7 | B9: JUDGES | C9: 3 | D9: E4 | E9: 82 | F9: 97 | G9: 117 | H9: 12 | I9: 249 | J9: 13 | K9: 36 | L9: 0 | M9: 16 | N9: 4 | O9: 128 | P9: 0
A10: 7 | B10: JUDGES | C10: 4 | D10: F4 | E10: 0 | F10: 0 | G10: 11 | H10: 1 | I10: 27 | J10: 0 | K10: 0 | L10: 0 | M10: 3 | N10: 1 | O10: 0 | P10: 0
A11: 7 | B11: JUDGES | C11: 6 | D11: A4 | E11: 46 | F11: 40 | G11: 23 | H11: 16 | I11: 78 | J11: 10 | K11: 15 | L11: 0 | M11: 0 | N11: 0 | O11: 65 | P11: 0
A12: 7 | B12: JUDGES | C12: 7 | D12: B4 | E12: 210 | F12: 48 | G12: 644 | H12: 27 | I12: 108 | J12: 9 | K12: 37 | L12: 0 | M12: 25 | N12: 38 | O12: 80 | P12: 0
A13: 7 | B13: JUDGES | C13: 8 | D13: C5 | E13: 6 | F13: 0 | G13: 186 | H13: 6 | I13: 467 | J13: 0 | K13: 2 | L13: 0 | M13: 0 | N13: 0 | O13: 6 | P13: 0

Sheet Samuel
A1: book seq | B1: book | C1: degree | D1: note | E1: Revia | F1: Azla | G1: Zaqef-qatan | H1: Zaqef-gadol | I1: Pashta | J1: Telisha-gedola | K1: Telisha-qetana | L1: Qarne | M1: Tsinnor | N1: Segol | O1: Qadma | P1: Shalshelet
A2: 8 | B2: 1 SAMUEL | C2: 3 | D2: E4 | E2: 132 | F2: 157 | G2: 147 | H2: 19 | I2: 290 | J2: 15 | K2: 49 | L2: 0 | M2: 7 | N2: 6 | O2: 214 | P2: 0 | Q2: =SUM(E2:P2) -> 1036
A3: 8 | B3: 1 SAMUEL | C3: 4 | D3: F4 | E3: 0 | F3: 0 | G3: 12 | H3: 1 | I3: 37 | J3: 0 | K3: 0 | L3: 0 | M3: 2 | N3: 2 | O3: 0 | P3: 0 | Q3: =SUM(E3:P3) -> 54
A4: 8 | B4: 1 SAMUEL | C4: 6 | D4: A4 | E4: 53 | F4: 37 | G4: 22 | H4: 26 | I4: 92 | J4: 7 | K4: 21 | L4: 0 | M4: 0 | N4: 0 | O4: 73 | P4: 0 | Q4: =SUM(E4:P4) -> 331
A5: 8 | B5: 1 SAMUEL | C5: 7 | D5: B4 | E5: 289 | F5: 52 | G5: 819 | H5: 23 | I5: 130 | J5: 26 | K5: 38 | L5: 0 | M5: 33 | N5: 32 | O5: 97 | P5: 0 | Q5: =SUM(E5:P5) -> 1539
A6: 8 | B6: 1 SAMUEL | C6: 8 | D6: C5 | E6: 7 | F6: 5 | G6: 325 | H6: 5 | I6: 698 | J6: 1 | K6: 3 | L6: 0 | M6: 0 | N6: 0 | O6: 19 | P6: 0 | Q6: =SUM(E6:P6) -> 1063
A7: book seq | B7: book | C7: degree | D7: note | E7: Revia | F7: Azla | G7: Zaqef-qatan | H7: Zaqef-gadol | I7: Pashta | J7: Telisha-gedola | K7: Telisha-qetana | L7: Qarne | M7: Tsinnor | N7: Segol | O7: Qadma | P7: Shalshelet | Q7: =SUM(Q2:Q6) -> 4023 | R7: 31316 | S7: =Q7/R7 -> 0.12846468
A8: 9 | B8: 2 SAMUEL | C8: 2 | D8: D4 | E8: 0 | F8: 1 | G8: 0 | H8: 0 | I8: 0 | J8: 0 | K8: 1 | L8: 1 | M8: 0 | N8: 0 | O8: 1 | P8: 0 | Q8: =SUM(E8:P8) -> 4
A9: 9 | B9: 2 SAMUEL | C9: 3 | D9: E4 | E9: 71 | F9: 95 | G9: 119 | H9: 23 | I9: 230 | J9: 15 | K9: 41 | L9: 0 | M9: 4 | N9: 3 | O9: 131 | P9: 0 | Q9: =SUM(E9:P9) -> 732
A10: 9 | B10: 2 SAMUEL | C10: 4 | D10: F4 | E10: 1 | F10: 0 | G10: 18 | H10: 1 | I10: 40 | J10: 0 | K10: 0 | L10: 0 | M10: 4 | N10: 3 | O10: 1 | P10: 0 | Q10: =SUM(E10:P10) -> 68
A11: 9 | B11: 2 SAMUEL | C11: 6 | D11: A4 | E11: 54 | F11: 44 | G11: 24 | H11: 22 | I11: 96 | J11: 4 | K11: 15 | L11: 0 | M11: 0 | N11: 0 | O11: 73 | P11: 0 | Q11: =SUM(E11:P11) -> 332
A12: 9 | B12: 2 SAMUEL | C12: 7 | D12: B4 | E12: 277 | F12: 43 | G12: 614 | H12: 26 | I12: 110 | J12: 25 | K12: 44 | L12: 0 | M12: 17 | N12: 18 | O12: 94 | P12: 0 | Q12: =SUM(E12:P12) -> 1268
A13: 9 | B13: 2 SAMUEL | C13: 8 | D13: C5 | E13: 9 | F13: 3 | G13: 239 | H13: 6 | I13: 575 | J13: 3 | K13: 1 | L13: 0 | M13: 0 | N13: 0 | O13: 8 | P13: 0 | Q13: =SUM(E13:P13) -> 844
Q14: =SUM(Q8:Q13) -> 3248 | R14: 25868 | S14: =Q14/R14 -> 0.12556054
E39: 1 Sam z-q | F39: =I1 -> Pashta | G39: 2 Sam z-q | H39: Pashta
D40: =D9 -> E4 | E40: =G2 -> 147 | F40: =I2 -> 290 | G40: =G9 -> 119 | H40: =I9 -> 230
D41: =D10 -> F4 | E41: =G3 -> 12 | F41: =I3 -> 37 | G41: =G10 -> 18 | H41: =I10 -> 40
D42: =D11 -> A4 | E42: =G4 -> 22 | F42: =I4 -> 92 | G42: =G11 -> 24 | H42: =I11 -> 96
D43: =D12 -> B4 | E43: =G5 -> 819 | F43: =I5 -> 130 | G43: =G12 -> 614 | H43: =I12 -> 110
D44: =D13 -> C5 | E44: =G6 -> 325 | F44: =I6 -> 698 | G44: =G13 -> 239 | H44: =I13 -> 575
E45: =SUM(E40:E44) -> 1325 | F45: =SUM(F40:F44) -> 1247 | G45: =SUM(G40:G44) -> 1014 | H45: =SUM(H40:H44) -> 1051
E46: =E45/$R$7 -> 0.04231064 | F46: =F45/$R$7 -> 0.0398199 | G46: =G45/$R$14 -> 0.03919901 | H46: =H45/$R$14 -> 0.040629349

Sheet Kings
A1: book seq | B1: book | C1: degree | D1: note | E1: Revia | F1: Azla | G1: Zaqef-qatan | H1: Zaqef-gadol | I1: Pashta | J1: Telisha-gedola | K1: Telisha-qetana | L1: Qarne | M1: Tsinnor | N1: Segol | O1: Qadma | P1: Shalshelet
A2: 10 | B2: 1 KINGS | C2: 3 | D2: E4 | E2: 111 | F2: 129 | G2: 129 | H2: 26 | I2: 286 | J2: 28 | K2: 61 | L2: 0 | M2: 16 | N2: 9 | O2: 214 | P2: 0
A3: 10 | B3: 1 KINGS | C3: 4 | D3: F4 | E3: 0 | F3: 0 | G3: 11 | H3: 0 | I3: 23 | J3: 0 | K3: 0 | L3: 0 | M3: 2 | N3: 2 | O3: 1 | P3: 0
A4: 10 | B4: 1 KINGS | C4: 6 | D4: A4 | E4: 51 | F4: 42 | G4: 25 | H4: 18 | I4: 112 | J4: 18 | K4: 15 | L4: 0 | M4: 0 | N4: 0 | O4: 75 | P4: 0
A5: 10 | B5: 1 KINGS | C5: 7 | D5: B4 | E5: 326 | F5: 56 | G5: 843 | H5: 32 | I5: 167 | J5: 29 | K5: 40 | L5: 0 | M5: 25 | N5: 31 | O5: 107 | P5: 0
A6: 10 | B6: 1 KINGS | C6: 8 | D6: C5 | E6: 4 | F6: 0 | G6: 222 | H6: 12 | I6: 636 | J6: 1 | K6: 2 | L6: 0 | M6: 0 | N6: 0 | O6: 12 | P6: 0
A7: book seq | B7: book | C7: degree | D7: note | E7: Revia | F7: Azla | G7: Zaqef-qatan | H7: Zaqef-gadol | I7: Pashta | J7: Telisha-gedola | K7: Telisha-qetana | L7: Qarne | M7: Tsinnor | N7: Segol | O7: Qadma | P7: Shalshelet
A8: 11 | B8: 2 KINGS | C8: 2 | D8: D4 | E8: 0 | F8: 0 | G8: 0 | H8: 0 | I8: 0 | J8: 0 | K8: 1 | L8: 1 | M8: 0 | N8: 0 | O8: 1 | P8: 0
A9: 11 | B9: 2 KINGS | C9: 3 | D9: E4 | E9: 100 | F9: 117 | G9: 119 | H9: 27 | I9: 278 | J9: 25 | K9: 58 | L9: 0 | M9: 15 | N9: 5 | O9: 173 | P9: 0
A10: 11 | B10: 2 KINGS | C10: 4 | D10: F4 | E10: 0 | F10: 0 | G10: 7 | H10: 1 | I10: 26 | J10: 0 | K10: 0 | L10: 0 | M10: 2 | N10: 1 | O10: 0 | P10: 0
A11: 11 | B11: 2 KINGS | C11: 6 | D11: A4 | E11: 53 | F11: 47 | G11: 31 | H11: 16 | I11: 80 | J11: 18 | K11: 14 | L11: 0 | M11: 0 | N11: 0 | O11: 77 | P11: 0
A12: 11 | B12: 2 KINGS | C12: 7 | D12: B4 | E12: 318 | F12: 70 | G12: 743 | H12: 22 | I12: 133 | J12: 32 | K12: 41 | L12: 0 | M12: 37 | N12: 41 | O12: 111 | P12: 0
A13: 11 | B13: 2 KINGS | C13: 8 | D13: C5 | E13: 4 | F13: 2 | G13: 200 | H13: 7 | I13: 570 | J13: 1 | K13: 0 | L13: 0 | M13: 0 | N13: 0 | O13: 9 | P13: 0

Sheet Isaiah
A1: book seq | B1: book | C1: degree | D1: note | E1: Revia | F1: Azla | G1: Zaqef-qatan | H1: Zaqef-gadol | I1: Pashta | J1: Telisha-gedola | K1: Telisha-qetana | L1: Qarne | M1: Tsinnor | N1: Segol | O1: Qadma | P1: Shalshelet
A2: 12 | B2: ISAIAH | C2: 3 | D2: E4 | E2: 98 | F2: 76 | G2: 204 | H2: 22 | I2: 374 | J2: 15 | K2: 23 | L2: 0 | M2: 7 | N2: 3 | O2: 140 | P2: 1
A3: 12 | B3: ISAIAH | C3: 4 | D3: F4 | E3: 0 | F3: 0 | G3: 27 | H3: 0 | I3: 54 | J3: 0 | K3: 0 | L3: 0 | M3: 0 | N3: 0 | O3: 0 | P3: 0
A4: 12 | B4: ISAIAH | C4: 6 | D4: A4 | E4: 42 | F4: 28 | G4: 42 | H4: 22 | I4: 214 | J4: 7 | K4: 10 | L4: 0 | M4: 0 | N4: 0 | O4: 62 | P4: 0
A5: 12 | B5: ISAIAH | C5: 7 | D5: B4 | E5: 257 | F5: 34 | G5: 1058 | H5: 13 | I5: 140 | J5: 15 | K5: 22 | L5: 0 | M5: 22 | N5: 22 | O5: 67 | P5: 0
A6: 12 | B6: ISAIAH | C6: 8 | D6: C5 | E6: 1 | F6: 0 | G6: 443 | H6: 5 | I6: 979 | J6: 0 | K6: 1 | L6: 0 | M6: 0 | N6: 0 | O6: 6 | P6: 0

Sheet Jeremiah
A1: book seq | B1: book | C1: degree | D1: note | E1: Revia | F1: Azla | G1: Zaefq-qatan | H1: Zaqef-gadol | I1: Pashta | J1: Telisha-gedola | K1: Telisha-qetana | L1: Qarne | M1: Tsinnor | N1: Segol | O1: Qadma | P1: Shalshelet
A2: 13 | B2: JEREMIAH | C2: 2 | D2: D4 | E2: 0 | F2: 1 | G2: 0 | H2: 0 | I2: 0 | J2: 0 | K2: 0 | L2: 2 | M2: 0 | N2: 0 | O2: 1 | P2: 0
A3: 13 | B3: JEREMIAH | C3: 3 | D3: E4 | E3: 193 | F3: 190 | G3: 251 | H3: 33 | I3: 498 | J3: 38 | K3: 89 | L3: 0 | M3: 18 | N3: 8 | O3: 278 | P3: 0
A4: 13 | B4: JEREMIAH | C4: 4 | D4: F4 | E4: 2 | F4: 0 | G4: 28 | H4: 1 | I4: 57 | J4: 0 | K4: 0 | L4: 0 | M4: 3 | N4: 1 | O4: 0 | P4: 0
A5: 13 | B5: JEREMIAH | C5: 6 | D5: A4 | E5: 71 | F5: 68 | G5: 43 | H5: 30 | I5: 175 | J5: 10 | K5: 34 | L5: 0 | M5: 0 | N5: 0 | O5: 117 | P5: 0
A6: 13 | B6: JEREMIAH | C6: 7 | D6: B4 | E6: 465 | F6: 108 | G6: 1288 | H6: 33 | I6: 213 | J6: 46 | K6: 53 | L6: 0 | M6: 44 | N6: 54 | O6: 175 | P6: 0
A7: 13 | B7: JEREMIAH | C7: 8 | D7: C5 | E7: 7 | F7: 1 | G7: 441 | H7: 7 | I7: 1042 | J7: 3 | K7: 2 | L7: 0 | M7: 0 | N7: 0 | O7: 18 | P7: 0

Sheet Ezekiel
A1: book seq | B1: book | C1: degree | D1: note | E1: Revia | F1: Azla | G1: Zaqef-qatan | H1: Zaqef-gadol | I1: Pashta | J1: Telisha-gedola | K1: Telisha-qetana | L1: Qarne | M1: Tsinnor | N1: Segol | O1: Tarsin | P1: Qadma | Q1: Pazer | R1: Shalshelet | T1: shalshelet
A2: 14 | B2: EZEKIEL | C2: 2 | D2: D4 | E2: 0 | F2: 0 | G2: 0 | H2: 0 | I2: 0 | J2: 0 | K2: 0 | L2: 1 | M2: 0 | N2: 0 | O2: 0 | P2: 0 | Q2: 0 | R2: 0 | S2: =SUM(E2:R2) -> 1 | T2: qarne-farah | U2: 1 | V2: =U2=L8 -> TRUE
A3: 14 | B3: EZEKIEL | C3: 3 | D3: E4 | E3: 188 | F3: 152 | G3: 183 | H3: 49 | I3: 407 | J3: 22 | K3: 55 | L3: 0 | M3: 25 | N3: 6 | O3: 65 | P3: 231 | Q3: 25 | R3: 0 | S3: =SUM(E3:R3) -> 1408 | T3: pazer | U3: 63 | V3: =U3=Q8 -> TRUE
A4: 14 | B4: EZEKIEL | C4: 4 | D4: F4 | E4: 1 | F4: 0 | G4: 16 | H4: 0 | I4: 46 | J4: 0 | K4: 0 | L4: 0 | M4: 2 | N4: 1 | O4: 0 | P4: 1 | Q4: 0 | R4: 0 | S4: =SUM(E4:R4) -> 67 | T4: telisha-gedola | U4: 68 | V4: =U4=J8 -> TRUE
A5: 14 | B5: EZEKIEL | C5: 6 | D5: A4 | E5: 61 | F5: 69 | G5: 42 | H5: 38 | I5: 154 | J5: 9 | K5: 25 | L5: 0 | M5: 0 | N5: 0 | O5: 20 | P5: 117 | Q5: 3 | R5: 0 | S5: =SUM(E5:R5) -> 538 | T5: segol | U5: 70
A6: 14 | B6: EZEKIEL | C6: 7 | D6: B4 | E6: 411 | F6: 68 | G6: 1234 | H6: 41 | I6: 216 | J6: 37 | K6: 42 | L6: 0 | M6: 43 | N6: 63 | O6: 21 | P6: 125 | Q6: 35 | R6: 0 | S6: =SUM(E6:R6) -> 2336 | T6: tsinnor | U6: 70
A7: 14 | B7: EZEKIEL | C7: 8 | D7: C5 | E7: 5 | F7: 2 | G7: 384 | H7: 12 | I7: 1019 | J7: 0 | K7: 0 | L7: 0 | M7: 0 | N7: 0 | O7: 0 | P7: 7 | Q7: 0 | R7: 0 | S7: =SUM(E7:R7) -> 1429 | T7: tarsin | U7: 106 | V7: missing
E8: =SUM(E2:E7) -> 666 | F8: =SUM(F2:F7) -> 291 | G8: =SUM(G2:G7) -> 1859 | H8: =SUM(H2:H7) -> 140 | I8: =SUM(I2:I7) -> 1842 | J8: =SUM(J2:J7) -> 68 | K8: =SUM(K2:K7) -> 122 | L8: =SUM(L2:L7) -> 1 | ... R8: =SUM(R2:R7) -> 0 | S8: =SUM(E8:R8) -> 5779 | T8: telisha-qetana | U8: 122
T9: zaqef-gadol | U9: 140
T10: azla | U10: 291
T11: qadma | U11: 481
T12: revia | U12: 666
T13: pashta | U13: 1842
T14: zaqef-qatan | U14: 1859
U15: =SUM(U2:U14) -> 5779

Sheet The-Twelve
A1: book seq | B1: book | C1: degree | D1: note | E1: Revia | F1: Azla | G1: Zaqef-qatan | H1: Zaqef-gadol | I1: Pashta | J1: Telisha-gedola | K1: Telisha-qetana | L1: Qarne | M1: Tsinnor | N1: Segol | O1: Qadma | P1: Shalshelet
A2: 15 | B2: HOSEA | C2: 3 | D2: E4 | E2: 14 | F2: 9 | G2: 37 | H2: 10 | I2: 60 | J2: 3 | K2: 0 | L2: 0 | M2: 0 | N2: 0 | O2: 14 | P2: 0 | Q2: =SUM(E2:P2) -> 147
A3: 15 | B3: HOSEA | C3: 4 | D3: F4 | E3: 0 | F3: 0 | G3: 5 | H3: 0 | I3: 15 | J3: 0 | K3: 0 | L3: 0 | M3: 1 | N3: 0 | O3: 0 | P3: 0 | Q3: =SUM(E3:P3) -> 21
A4: 15 | B4: HOSEA | C4: 6 | D4: A4 | E4: 8 | F4: 5 | G4: 4 | H4: 7 | I4: 28 | J4: 0 | K4: 1 | L4: 0 | M4: 0 | N4: 0 | O4: 7 | P4: 0 | Q4: =SUM(E4:P4) -> 60
A5: 15 | B5: HOSEA | C5: 7 | D5: B4 | E5: 38 | F5: 2 | G5: 158 | H5: 3 | I5: 23 | J5: 1 | K5: 2 | L5: 0 | M5: 1 | N5: 2 | O5: 7 | P5: 0 | Q5: =SUM(E5:P5) -> 237
A6: 15 | B6: HOSEA | C6: 8 | D6: C5 | E6: 0 | F6: 0 | G6: 60 | H6: 0 | I6: 112 | J6: 0 | K6: 0 | L6: 0 | M6: 0 | N6: 0 | O6: 0 | P6: 0 | Q6: =SUM(E6:P6) -> 172
E7: =SUM(E2:E6) -> 60 | F7: =SUM(F2:F6) -> 16 | G7: =SUM(G2:G6) -> 264 | H7: =SUM(H2:H6) -> 20 | I7: =SUM(I2:I6) -> 238 | J7: =SUM(J2:J6) -> 4 | K7: =SUM(K2:K6) -> 3 | L7: =SUM(L2:L6) -> 0 | ... P7: =SUM(P2:P6) -> 0 | Q7: =SUM(E7:P7) -> 637
A8: book seq | B8: book | C8: degree | D8: note | E8: Revia | F8: Azla | G8: Zaqef-qatan | H8: Zaqef-gadol | I8: Pashta | J8: Telisha-gedola | K8: Telisha-qetana | L8: Qarne | M8: Tsinnor | N8: Segol | O8: Qadma | P8: Shalshelet
A9: 16 | B9: JOEL | C9: 3 | D9: E4 | E9: 8 | F9: 4 | G9: 19 | H9: 2 | I9: 34 | J9: 1 | K9: 1 | L9: 0 | M9: 0 | N9: 0 | O9: 4 | P9: 0 | Q9: =SUM(E9:P9) -> 73
A10: 16 | B10: JOEL | C10: 4 | D10: F4 | E10: 0 | F10: 0 | G10: 0 | H10: 0 | I10: 1 | J10: 0 | K10: 0 | L10: 0 | M10: 0 | N10: 0 | O10: 0 | P10: 0 | Q10: =SUM(E10:P10) -> 1
A11: 16 | B11: JOEL | C11: 6 | D11: A4 | E11: 5 | F11: 3 | G11: 3 | H11: 2 | I11: 8 | J11: 1 | K11: 0 | L11: 0 | M11: 0 | N11: 0 | O11: 5 | P11: 0 | Q11: =SUM(E11:P11) -> 27
A12: 16 | B12: JOEL | C12: 7 | D12: B4 | E12: 22 | F12: 0 | G12: 72 | H12: 2 | I12: 15 | J12: 0 | K12: 0 | L12: 0 | M12: 1 | N12: 1 | O12: 4 | P12: 0 | Q12: =SUM(E12:P12) -> 117
A13: 16 | B13: JOEL | C13: 8 | D13: C5 | E13: 1 | F13: 0 | G13: 21 | H13: 0 | I13: 46 | J13: 0 | K13: 0 | L13: 0 | M13: 0 | N13: 0 | O13: 0 | P13: 0 | Q13: =SUM(E13:P13) -> 68
E14: =SUM(E9:E13) -> 36 | F14: =SUM(F9:F13) -> 7 | G14: =SUM(G9:G13) -> 115 | H14: =SUM(H9:H13) -> 6 | I14: =SUM(I9:I13) -> 104 | J14: =SUM(J9:J13) -> 2 | K14: =SUM(K9:K13) -> 1 | L14: =SUM(L9:L13) -> 0 | ... P14: =SUM(P9:P13) -> 0 | Q14: =SUM(E14:P14) -> 286
A15: book seq | B15: book | C15: degree | D15: note | E15: Revia | F15: Azla | G15: Zaqef-qatan | H15: Zaqef-gadol | I15: Pashta | J15: Telisha-gedola | K15: Telisha-qetana | L15: Qarne | M15: Tsinnor | N15: Segol | O15: Qadma | P15: Shalshelet
A16: 17 | B16: AMOS | C16: 3 | D16: E4 | E16: 18 | F16: 18 | G16: 19 | H16: 2 | I16: 35 | J16: 3 | K16: 6 | L16: 0 | M16: 2 | N16: 0 | O16: 21 | P16: 1 | Q16: =SUM(E16:P16) -> 125
A17: 17 | B17: AMOS | C17: 4 | D17: F4 | E17: 0 | F17: 0 | G17: 1 | H17: 0 | I17: 5 | J17: 0 | K17: 0 | L17: 0 | M17: 0 | N17: 0 | O17: 0 | P17: 0 | Q17: =SUM(E17:P17) -> 6
A18: 17 | B18: AMOS | C18: 6 | D18: A4 | E18: 9 | F18: 6 | G18: 2 | H18: 1 | I18: 13 | J18: 1 | K18: 1 | L18: 0 | M18: 0 | N18: 0 | O18: 12 | P18: 0 | Q18: =SUM(E18:P18) -> 45
A19: 17 | B19: AMOS | C19: 7 | D19: B4 | E19: 26 | F19: 3 | G19: 119 | H19: 1 | I19: 20 | J19: 0 | K19: 3 | L19: 0 | M19: 2 | N19: 4 | O19: 9 | P19: 0 | Q19: =SUM(E19:P19) -> 187
A20: 17 | B20: AMOS | C20: 8 | D20: C5 | E20: 0 | F20: 0 | G20: 57 | H20: 1 | I20: 118 | J20: 0 | K20: 0 | L20: 0 | M20: 0 | N20: 0 | O20: 2 | P20: 0 | Q20: =SUM(E20:P20) -> 178
E21: =SUM(E16:E20) -> 53 | F21: =SUM(F16:F20) -> 27 | G21: =SUM(G16:G20) -> 198 | H21: =SUM(H16:H20) -> 5 | I21: =SUM(I16:I20) -> 191 | J21: =SUM(J16:J20) -> 4 | K21: =SUM(K16:K20) -> 10 | L21: =SUM(L16:L20) -> 0 | ... P21: =SUM(P16:P20) -> 1 | Q21: =SUM(E21:P21) -> 541
A22: book seq | B22: book | C22: degree | D22: note | E22: Revia | F22: Azla | G22: Zaqef-qatan | H22: Zaqef-gadol | I22: Pashta | J22: Telisha-gedola | K22: Telisha-qetana | L22: Qarne | M22: Tsinnor | N22: Segol | O22: Qadma | P22: Shalshelet
A23: 18 | B23: OBADIAH | C23: 3 | D23: E4 | E23: 2 | F23: 4 | G23: 2 | H23: 0 | I23: 8 | J23: 1 | K23: 2 | L23: 0 | M23: 0 | N23: 0 | O23: 5 | P23: 0 | Q23: =SUM(E23:P23) -> 24
A24: 18 | B24: OBADIAH | C24: 6 | D24: A4 | E24: 1 | F24: 0 | G24: 0 | H24: 1 | I24: 0 | J24: 0 | K24: 0 | L24: 0 | M24: 0 | N24: 0 | O24: 0 | P24: 0 | Q24: =SUM(E24:P24) -> 2
A25: 18 | B25: OBADIAH | C25: 7 | D25: B4 | E25: 4 | F25: 0 | G25: 21 | H25: 0 | I25: 4 | J25: 0 | K25: 0 | L25: 0 | M25: 0 | N25: 0 | O25: 0 | P25: 0 | Q25: =SUM(E25:P25) -> 29
A26: 18 | B26: OBADIAH | C26: 8 | D26: C5 | E26: 0 | F26: 0 | G26: 3 | H26: 0 | I26: 12 | J26: 0 | K26: 0 | L26: 0 | M26: 0 | N26: 0 | O26: 0 | P26: 0 | Q26: =SUM(E26:P26) -> 15
E27: =SUM(E23:E26) -> 7 | F27: =SUM(F23:F26) -> 4 | G27: =SUM(G23:G26) -> 26 | H27: =SUM(H23:H26) -> 1 | I27: =SUM(I23:I26) -> 24 | J27: =SUM(J23:J26) -> 1 | K27: =SUM(K23:K26) -> 2 | L27: =SUM(L23:L26) -> 0 | ... P27: =SUM(P23:P26) -> 0 | Q27: =SUM(E27:P27) -> 70
A28: book seq | B28: book | C28: degree | D28: note | E28: Revia | F28: Azla | G28: Zaqef-qatan | H28: Zaqef-gadol | I28: Pashta | J28: Telisha-gedola | K28: Telisha-qetana | L28: Qarne | M28: Tsinnor | N28: Segol | O28: Qadma | P28: Shalshelet
A29: 19 | B29: JONAH | C29: 3 | D29: E4 | E29: 8 | F29: 3 | G29: 14 | H29: 0 | I29: 16 | J29: 3 | K29: 0 | L29: 0 | M29: 1 | N29: 0 | O29: 4 | P29: 0 | Q29: =SUM(E29:P29) -> 49
A30: 19 | B30: JONAH | C30: 4 | D30: F4 | E30: 0 | F30: 0 | G30: 1 | H30: 0 | I30: 3 | J30: 0 | K30: 0 | L30: 0 | M30: 0 | N30: 0 | O30: 0 | P30: 0 | Q30: =SUM(E30:P30) -> 4
A31: 19 | B31: JONAH | C31: 6 | D31: A4 | E31: 3 | F31: 3 | G31: 1 | H31: 1 | I31: 6 | J31: 0 | K31: 1 | L31: 0 | M31: 0 | N31: 0 | O31: 3 | P31: 0 | Q31: =SUM(E31:P31) -> 18
A32: 19 | B32: JONAH | C32: 7 | D32: B4 | E32: 15 | F32: 3 | G32: 43 | H32: 0 | I32: 7 | J32: 0 | K32: 1 | L32: 0 | M32: 0 | N32: 1 | O32: 3 | P32: 0 | Q32: =SUM(E32:P32) -> 73
A33: 19 | B33: JONAH | C33: 8 | D33: C5 | E33: 0 | F33: 0 | G33: 13 | H33: 1 | I33: 34 | J33: 0 | K33: 0 | L33: 0 | M33: 0 | N33: 0 | O33: 0 | P33: 0 | Q33: =SUM(E33:P33) -> 48
E34: =SUM(E29:E33) -> 26 | F34: =SUM(F29:F33) -> 9 | G34: =SUM(G29:G33) -> 72 | H34: =SUM(H29:H33) -> 2 | I34: =SUM(I29:I33) -> 66 | J34: =SUM(J29:J33) -> 3 | K34: =SUM(K29:K33) -> 2 | L34: =SUM(L29:L33) -> 0 | ... P34: =SUM(P29:P33) -> 0 | Q34: =SUM(E34:P34) -> 192
A35: book seq | B35: book | C35: degree | D35: note | E35: Revia | F35: Azla | G35: Zaqef-qatan | H35: Zaqef-gadol | I35: Pashta | J35: Telisha-gedola | K35: Telisha-qetana | L35: Qarne | M35: Tsinnor | N35: Segol | O35: Qadma | P35: Shalshelet
A36: 20 | B36: MICAH | C36: 3 | D36: E4 | E36: 17 | F36: 6 | G36: 20 | H36: 2 | I36: 42 | J36: 0 | K36: 2 | L36: 0 | M36: 0 | N36: 0 | O36: 5 | P36: 0 | Q36: =SUM(E36:P36) -> 94
A37: 20 | B37: MICAH | C37: 4 | D37: F4 | E37: 0 | F37: 0 | G37: 1 | H37: 0 | I37: 4 | J37: 0 | K37: 0 | L37: 0 | M37: 0 | N37: 0 | O37: 0 | P37: 0 | Q37: =SUM(E37:P37) -> 5
A38: 20 | B38: MICAH | C38: 6 | D38: A4 | E38: 5 | F38: 3 | G38: 4 | H38: 2 | I38: 20 | J38: 2 | K38: 3 | L38: 0 | M38: 0 | N38: 0 | O38: 9 | P38: 0 | Q38: =SUM(E38:P38) -> 48
A39: 20 | B39: MICAH | C39: 7 | D39: B4 | E39: 22 | F39: 0 | G39: 107 | H39: 2 | I39: 21 | J39: 1 | K39: 0 | L39: 0 | M39: 1 | N39: 1 | O39: 1 | P39: 0 | Q39: =SUM(E39:P39) -> 156
A40: 20 | B40: MICAH | C40: 8 | D40: C5 | E40: 0 | F40: 0 | G40: 30 | H40: 0 | I40: 67 | J40: 0 | K40: 0 | L40: 0 | M40: 0 | N40: 0 | O40: 1 | P40: 0 | Q40: =SUM(E40:P40) -> 98
...

Sheet Daniel-E-N
A1: book seq | B1: book | C1: degree | D1: note | E1: Revia | F1: Azla | G1: Zaqef-qatan | H1: Zaqef-gadol | I1: Pashta | J1: Telisha-gedola | K1: Telisha-qetana | L1: Qarne | M1: Tsinnor | N1: Segol | O1: Qadma | P1: Shalshelet
A2: 35 | B2: DANIEL | C2: 3 | D2: E4 | E2: 59 | F2: 57 | G2: 86 | H2: 5 | I2: 160 | J2: 16 | K2: 13 | L2: 0 | M2: 6 | N2: 5 | O2: 61 | P2: 0
A3: 35 | B3: DANIEL | C3: 4 | D3: F4 | E3: 0 | F3: 0 | G3: 4 | H3: 0 | I3: 7 | J3: 0 | K3: 0 | L3: 0 | M3: 2 | N3: 0 | O3: 1 | P3: 0
A4: 35 | B4: DANIEL | C4: 6 | D4: A4 | E4: 24 | F4: 25 | G4: 14 | H4: 18 | I4: 66 | J4: 3 | K4: 6 | L4: 0 | M4: 0 | N4: 0 | O4: 35 | P4: 0
A5: 35 | B5: DANIEL | C5: 7 | D5: B4 | E5: 165 | F5: 19 | G5: 428 | H5: 15 | I5: 94 | J5: 15 | K5: 24 | L5: 0 | M5: 14 | N5: 16 | O5: 49 | P5: 0
A6: 35 | B6: DANIEL | C6: 8 | D6: C5 | E6: 0 | F6: 0 | G6: 97 | H6: 2 | I6: 278 | J6: 0 | K6: 0 | L6: 0 | M6: 0 | N6: 0 | O6: 5 | P6: 0
A7: book seq | B7: book | C7: degree | D7: note | E7: Revia | F7: Azla | G7: Zaqef-qatan | H7: Zaqef-gadol | I7: Pashta | J7: Telisha-gedola | K7: Telisha-qetana | L7: Qarne | M7: Tsinnor | N7: Segol | O7: Qadma | P7: Shalshelet
A8: 36 | B8: EZRA | C8: 2 | D8: D4 | E8: 0 | F8: 0 | G8: 0 | H8: 0 | I8: 0 | J8: 0 | K8: 0 | L8: 1 | M8: 0 | N8: 0 | O8: 0 | P8: 0
A9: 36 | B9: EZRA | C9: 3 | D9: E4 | E9: 36 | F9: 29 | G9: 58 | H9: 5 | I9: 97 | J9: 14 | K9: 12 | L9: 0 | M9: 10 | N9: 1 | O9: 39 | P9: 1
A10: 36 | B10: EZRA | C10: 4 | D10: F4 | E10: 0 | F10: 0 | G10: 5 | H10: 0 | I10: 12 | J10: 0 | K10: 0 | L10: 0 | M10: 0 | N10: 0 | O10: 0 | P10: 0
A11: 36 | B11: EZRA | C11: 6 | D11: A4 | E11: 11 | F11: 11 | G11: 7 | H11: 14 | I11: 15 | J11: 5 | K11: 7 | L11: 0 | M11: 0 | N11: 0 | O11: 25 | P11: 0
A12: 36 | B12: EZRA | C12: 7 | D12: B4 | E12: 97 | F12: 18 | G12: 244 | H12: 12 | I12: 45 | J12: 16 | K12: 10 | L12: 0 | M12: 6 | N12: 15 | O12: 32 | P12: 0
A13: 36 | B13: EZRA | C13: 8 | D13: C5 | E13: 0 | F13: 0 | G13: 43 | H13: 3 | I13: 140 | J13: 1 | K13: 0 | L13: 0 | M13: 0 | N13: 0 | O13: 2 | P13: 0
